Workbook

Sheet Summary
A1: SAIL - Ratio Analysis, Cash Flow Statement and Financial Model
A2: Case: Steel Authority of India Ltd, FY2015-FY2019 (Test Yourself Q3, Lesson 14 Business Model Analysis, PP-V&BM, pp. 447-453)
A4: WHAT IS IN THIS WORKBOOK
A5: BS / PL: the source balance sheet and P&L (blue = hard-coded input; totals are formulas and tie to the source).
A6: CashFlow: cash flow statement derived (indirect method) from the two balance sheets and the P&L, FY16-FY19; reconciles exactly to balance-sheet cash.
A7: Ratios: liquidity, leverage, profitability, per-share, efficiency, DuPont and cash-flow ratios for FY15-FY19, with the source's published ratios alongside.
A8: Assumptions: every forecast driver in its own cell (blue on yellow = editable).
A9: Model: integrated income statement, balance sheet and cash flow FY20E-FY24E, with balance and cash checks.
A10: Valuation: FCFF DCF with CAPM-based WACC and a WACC / terminal-growth sensitivity grid.
A12: COLOUR CODE
A13: Blue text = hard-coded input | Black = formula | Green = link to another sheet | Yellow fill = forecast / key input to edit.
A15: MODEL INTEGRITY CHECKS (all must show OK)
A16: Source balance sheet balances (FY15-FY19) | C16: =IF(SUMPRODUCT(ABS(BS!C42:G42))<0.05,"OK","ERROR") -> OK
A17: Derived closing cash = balance-sheet cash (FY16-FY19) | C17: =IF(SUMPRODUCT(ABS(CashFlow!D43:G43))<0.05,"OK","ERROR") -> OK
A18: Model history PAT = reported PAT | C18: =IF(SUMPRODUCT(ABS(Model!C26:G26))<0.05,"OK","ERROR") -> OK
A19: Forecast balance sheet balances (FY20E-FY24E) | C19: =IF(SUMPRODUCT(ABS(Model!H52:L52))<0.05,"OK","ERROR") -> OK
A20: Forecast cash flow ties to balance-sheet cash | C20: =IF(SUMPRODUCT(ABS(Model!H71:L71))<0.05,"OK","ERROR") -> OK
A21: Forecast cash never negative | C21: =IF(MIN(Model!H48:L48)>=0,"OK","CHECK FINANCING") -> OK
A23: KEY OUTPUTS
A24: FY19 net profit (Rs. cr) | C24: =PL!G33 -> 2178.82
A25: FY19 return on net worth | C25: =Ratios!G24 -> 0.057109576
A26: FY19 debt-equity (x) | C26: =Ratios!G12 -> 1.0860334
A27: FY19 derived operating cash flow (Rs. cr) | C27: =CashFlow!G25 -> 7551.78
A28: FY24E revenue (Rs. cr) | C28: =Model!L6 -> 90454.763
A29: FY24E EBITDA margin | C29: =Model!L12 -> 0.138
A30: FY24E PAT (Rs. cr) | C30: =Model!L21 -> 5375.6403
A31: FY24E net debt / EBITDA (x) | C31: =Model!L80 -> 1.9881303
A32: DCF enterprise value (Rs. cr) | C32: =Valuation!C33 -> 75291.224
A33: DCF intrinsic value per share (Rs.) | C33: =Valuation!C39 -> 86.336412
A35: KEY NOTES AND ASSUMPTIONS
A36: 1. Source figures are as given in the study material (originally moneycontrol.com); they are not independently audited here.
A37: 2. Derived cash flow: capex = change in net fixed assets + depreciation; dividends assumed paid in the year declared; interest paid = P&L finance cost.
A38: 3. The source's own cash flow (shown under CashFlow for comparison) uses its own classification and a cash definition that differs from the balance sheet.
A39: 4. Source ratios are published using moneycontrol's definitions; the Ratios sheet uses standard textbook formulas, so some values differ (shown side by side).
A40: 5. FY16 derived cash flow is distorted (large CFO/CFI offsets): the FY15 balance sheet carries reclassified items (DTL/DTA, loans and advances) that move between lines in FY16; the total cash change still reconciles.
A41: 6. FY19 dividend: source shows a 5% rate in the ratios but Rs. 0 dividend amount in the P&L; the amount (0) is used.
A42: 7. Forecast drivers are illustrative management-style assumptions, not guidance. Tax is taken as a cash tax at the stated rate; DTA/DTL held flat.
A43: 8. Interest is charged on opening borrowings to avoid circular references. DDT applies in FY20E only (abolished from 1-Apr-2020).
A44: 9. DCF: end-of-year discounting, valuation date 31-Mar-2019, non-operating other income excluded from FCFF; WACC inputs are assumptions.

Sheet BS
A1: Steel Authority of India Ltd - Balance Sheet
A2: Rs. crore | 31 March | source data (blue = hard-coded input)
A4: Particulars | B4: Note | C4: FY15 | D4: FY16 | E4: FY17 | F4: FY18 | G4: FY19
A5: EQUITY AND LIABILITIES
A6: Equity share capital | C6: 4130.53 | D6: 4130.53 | E6: 4130.53 | F6: 4130.53 | G6: 4130.53
A7: Reserves and surplus | C7: 39374.25 | D7: 35065.37 | E7: 31878.53 | F7: 31583.14 | G7: 34021.04
A8: Total shareholders' funds | C8: =C6+C7 -> 43504.78 | D8: =D6+D7 -> 39195.9 | E8: =E6+E7 -> 36009.06 | F8: =F6+F7 -> 35713.67 | G8: =G6+G7 -> 38151.57
A9: NON-CURRENT LIABILITIES
A10: Long-term borrowings | C10: 14025.56 | D10: 17495.71 | E10: 19087.48 | F10: 29777.16 | G10: 30802.66
A11: Deferred tax liabilities (net) | C11: 2395.19 | D11: 0 | E11: 0 | F11: 0 | G11: 0
A12: Other long-term liabilities | C12: 1239.22 | D12: 1692.13 | E12: 1524.58 | F12: 1324.07 | G12: 1590.63
A13: Long-term provisions | C13: 3705.34 | D13: 3271.65 | E13: 3593.94 | F13: 3973.28 | G13: 4295.41
A14: Total non-current liabilities | C14: =C10+C11+C12+C13 -> 21365.31 | D14: =D10+D11+D12+D13 -> 22459.49 | E14: =E10+E11+E12+E13 -> 24206 | F14: =F10+F11+F12+F13 -> 35074.51 | G14: =G10+G11+G12+G13 -> 36688.7
A15: CURRENT LIABILITIES
A16: Short-term borrowings | C16: 14195.16 | D16: 15574.86 | E16: 19813.04 | F16: 12244.32 | G16: 10631.22
A17: Trade payables | C17: 3606.38 | D17: 4002.71 | E17: 5219.2 | F17: 7540.5 | G17: 7257.99
A18: Other current liabilities | C18: 14016.53 | D18: 16464.66 | E18: 18377.4 | F18: 21312.62 | G18: 21399.48
A19: Short-term provisions | C19: 2638.71 | D19: 2642.65 | E19: 2914.77 | F19: 2304.18 | G19: 2308.77
A20: Total current liabilities | C20: =C16+C17+C18+C19 -> 34456.78 | D20: =D16+D17+D18+D19 -> 38684.88 | E20: =E16+E17+E18+E19 -> 46324.41 | F20: =F16+F17+F18+F19 -> 43401.62 | G20: =G16+G17+G18+G19 -> 41597.46
A21: TOTAL CAPITAL AND LIABILITIES | C21: =C8+C14+C20 -> 99326.87 | D21: =D8+D14+D20 -> 100340.27 | E21: =E8+E14+E20 -> 106539.47 | F21: =F8+F14+F20 -> 114189.8 | G21: =G8+G14+G20 -> 116437.73
A23: ASSETS
A24: Tangible assets | C24: 34658.4 | D24: 44378.87 | E24: 48762.03 | F24: 57156.09 | G24: 59907.26
A25: Intangible assets | C25: 1510.21 | D25: 1546.2 | E25: 1522.58 | F25: 1454.63 | G25: 1450.86
A26: Capital work-in-progress | C26: 29195.82 | D26: 24927.22 | E26: 23275.39 | F26: 18395.43 | G26: 16013.5
A27: Other assets | C27: 0 | D27: 0.88 | E27: 0.86 | F27: 0.83 | G27: 1.09
A28: Fixed assets (incl. CWIP) | C28: =C24+C25+C26+C27 -> 65364.43 | D28: =D24+D25+D26+D27 -> 70853.17 | E28: =E24+E25+E26+E27 -> 73560.86 | F28: =F24+F25+F26+F27 -> 77006.98 | G28: =G24+G25+G26+G27 -> 77372.71
A29: Non-current investments | C29: 919.07 | D29: 1291.75 | E29: 1395.48 | F29: 1491.3 | G29: 1584.75
A30: Deferred tax assets (net) | C30: 0 | D30: 1799.8 | E30: 4005.84 | F30: 4185.27 | G30: 2898.38
A31: Long-term loans and advances | C31: 4507.25 | D31: 449.95 | E31: 453.52 | F31: 451.46 | G31: 563.98
A32: Other non-current assets | C32: 53.83 | D32: 1746.95 | E32: 1578.35 | F32: 1416.59 | G32: 1768.64
A33: Total non-current assets | C33: =C28+C29+C30+C31+C32 -> 70844.58 | D33: =D28+D29+D30+D31+D32 -> 76141.62 | E33: =E28+E29+E30+E31+E32 -> 80994.05 | F33: =F28+F29+F30+F31+F32 -> 84551.6 | G33: =G28+G29+G30+G31+G32 -> 84188.46
A34: Inventories | C34: 17736.37 | D34: 14679.53 | E34: 15711.35 | F34: 16996.67 | G34: 19441.8
A35: Trade receivables | C35: 3192 | D35: 3143.49 | E35: 2921.69 | F35: 3869.94 | G35: 4495.05
A36: Cash and cash equivalents | C36: 2305.24 | D36: 297.96 | E36: 289.09 | F36: 254.06 | G36: 219.42
A37: Short-term loans and advances | C37: 3056.33 | D37: 64.09 | E37: 61.47 | F37: 63.41 | G37: 53.24
A38: Other current assets | C38: 2192.35 | D38: 6013.58 | E38: 6561.82 | F38: 8454.12 | G38: 8039.76
A39: Total current assets | C39: =C34+C35+C36+C37+C38 -> 28482.29 | D39: =D34+D35+D36+D37+D38 -> 24198.65 | E39: =E34+E35+E36+E37+E38 -> 25545.42 | F39: =F34+F35+F36+F37+F38 -> 29638.2 | G39: =G34+G35+G36+G37+G38 -> 32249.27
A40: TOTAL ASSETS | C40: =C33+C39 -> 99326.87 | D40: =D33+D39 -> 100340.27 | E40: =E33+E39 -> 106539.47 | F40: =F33+F39 -> 114189.8 | G40: =G33+G39 -> 116437.73
A42: Check: total assets - total capital & liabilities (must be 0) | C42: =ROUND(C40-C21,2) -> 0 | D42: =ROUND(D40-D21,2) -> 0 | E42: =ROUND(E40-E21,2) -> 0 | F42: =ROUND(F40-F21,2) -> 0 | G42: =ROUND(G40-G21,2) -> 0

Sheet PL
A1: Steel Authority of India Ltd - Profit & Loss Account
A2: Rs. crore | year ended 31 March | source data (blue = hard-coded input)
A4: Particulars | B4: Note | C4: FY15 | D4: FY16 | E4: FY17 | F4: FY18 | G4: FY19
A5: INCOME
A6: Revenue from operations [gross] | C6: 50650.76 | D6: 43327.5 | E6: 49212.13 | F6: 58320.82 | G6: 66295.83
A7: Less: excise / service tax / other levies | C7: 5418.6 | D7: 4823.29 | E7: 5314.69 | F7: 1403.9 | G7: 0
A8: Revenue from operations [net] | C8: =C6-C7 -> 45232.16 | D8: =D6-D7 -> 38504.21 | E8: =E6-E7 -> 43897.44 | F8: =F6-F7 -> 56916.92 | G8: =G6-G7 -> 66295.83
A9: Other operating revenues | C9: 478.62 | D9: 547.67 | E9: 554.97 | F9: 641.54 | G9: 671.48
A10: Total operating revenues | C10: =C8+C9 -> 45710.78 | D10: =D8+D9 -> 39051.88 | E10: =E8+E9 -> 44452.41 | F10: =F8+F9 -> 57558.46 | G10: =G8+G9 -> 66967.31
A11: Other income | C11: 1020.78 | D11: 594.67 | E11: 535.61 | F11: 484.45 | G11: 532.82
A12: Total revenue | C12: =C10+C11 -> 46731.56 | D12: =D10+D11 -> 39646.55 | E12: =E10+E11 -> 44988.02 | F12: =F10+F11 -> 58042.91 | G12: =G10+G11 -> 67500.13
A13: EXPENSES
A14: Cost of materials consumed | C14: 18522.9 | D14: 17155.23 | E14: 21125.7 | F14: 26678.81 | G14: 32290.91
A15: Purchase of stock-in-trade | C15: 0.48 | D15: 0 | E15: 0 | F15: 0 | G15: 0
A16: Changes in inventories of FG, WIP and stock-in-trade | C16: -1408.12 | D16: 540.61 | E16: 120.63 | F16: 1135.49 | G16: -2716.62
A17: Employee benefit expenses | C17: 9736.33 | D17: 9714.97 | E17: 8947.83 | F17: 8850.07 | G17: 8830.34
A18: Finance costs | C18: 1454.23 | D18: 2300.45 | E18: 2527.82 | F18: 2822.75 | G18: 3154.92
A19: Depreciation and amortisation expenses | C19: 1773.28 | D19: 2402.35 | E19: 2679.95 | F19: 3064.92 | G19: 3384.72
A20: Other expenses | C20: 14205.32 | D20: 14540.44 | E20: 14220.21 | F20: 16276.24 | G20: 18828.57
A21: Total expenses | C21: =C14+C15+C16+C17+C18+C19+C20 -> 44284.42 | D21: =D14+D15+D16+D17+D18+D19+D20 -> 46654.05 | E21: =E14+E15+E16+E17+E18+E19+E20 -> 49622.14 | F21: =F14+F15+F16+F17+F18+F19+F20 -> 58828.28 | G21: =G14+G15+G16+G17+G18+G19+G20 -> 63772.84
A22: Profit/(loss) before exceptional items and tax | C22: =C12-C21 -> 2447.14 | D22: =D12-D21 -> -7007.5 | E22: =E12-E21 -> -4634.12 | F22: =F12-F21 -> -785.37 | G22: =G12-G21 -> 3727.29
A23: Exceptional items | C23: 0 | D23: 0 | E23: -216.74 | F23: 26.43 | G23: -389.4
A24: Profit/(loss) before tax | C24: =C22+C23 -> 2447.14 | D24: =D22+D23 -> -7007.5 | E24: =E22+E23 -> -4850.86 | F24: =F22+F23 -> -758.94 | G24: =G22+G23 -> 3337.89
A25: TAX EXPENSE
A26: Current tax | C26: 499.15 | D26: 0 | E26: 0 | F26: 0 | G26: 0
A27: Less: MAT credit entitlement | C27: 499.15 | D27: 0 | E27: 0 | F27: 0 | G27: 0
A28: Deferred tax | C28: 282.76 | D28: -2909.55 | E28: -2032.76 | F28: -312.96 | G28: 1154.23
A29: Tax for earlier years | C29: -16.53 | D29: -76.51 | E29: 15.14 | F29: 35.73 | G29: 4.84
A30: Total tax expenses | C30: =C26-C27+C28+C29 -> 266.23 | D30: =D26-D27+D28+D29 -> -2986.06 | E30: =E26-E27+E28+E29 -> -2017.62 | F30: =F26-F27+F28+F29 -> -277.23 | G30: =G26-G27+G28+G29 -> 1159.07
A31: Profit/(loss) after tax, before extra-ordinary items | C31: =C24-C30 -> 2180.91 | D31: =D24-D30 -> -4021.44 | E31: =E24-E30 -> -2833.24 | F31: =F24-F30 -> -481.71 | G31: =G24-G30 -> 2178.82
A32: Prior period items | C32: -88.23 | D32: 0 | E32: 0 | F32: 0 | G32: 0
A33: PROFIT/(LOSS) FOR THE PERIOD | C33: =C31+C32 -> 2092.68 | D33: =D31+D32 -> -4021.44 | E33: =E31+E32 -> -2833.24 | F33: =F31+F32 -> -481.71 | G33: =G31+G32 -> 2178.82
A34: PER SHARE AND DIVIDEND
A35: Basic EPS as reported (Rs.) | C35: 5.07 | D35: -9.74 | E35: -6.86 | F35: -1.17 | G35: 5.27
A36: Basic EPS recomputed = PAT / no. of shares (Rs.) | C36: =C33/(BS!C6/Assumptions!$C$6) -> 5.0663716 | D36: =D33/(BS!D6/Assumptions!$C$6) -> -9.7358935 | E36: =E33/(BS!E6/Assumptions!$C$6) -> -6.859265 | F36: =F33/(BS!F6/Assumptions!$C$6) -> -1.1662184 | G36: =G33/(BS!G6/Assumptions!$C$6) -> 5.2749163
A37: Equity share dividend | C37: 826.1 | D37: 103.26 | E37: 0 | F37: 0 | G37: 0 | I37: FY19: source shows 0 amount although a 5% rate is quoted; amount kept as reported
A38: Tax on dividend | C38: 164.79 | D38: 21.02 | E38: 0 | F38: 0 | G38: 0

Sheet CashFlow
A1: Steel Authority of India Ltd - Cash Flow Statement
A2: Rs. crore | derived by the indirect method from BS and P&L (FY16-FY19; FY15 needs an FY14 balance sheet)
A4: Particulars | B4: Note | C4: FY15 | D4: FY16 | E4: FY17 | F4: FY18 | G4: FY19
A5: A. CASH FLOW FROM OPERATING ACTIVITIES (indirect method, derived from BS and P&L)
A6: Profit/(loss) for the period | D6: =PL!D33 -> -4021.44 | E6: =PL!E33 -> -2833.24 | F6: =PL!F33 -> -481.71 | G6: =PL!G33 -> 2178.82
A7: Add: depreciation and amortisation | D7: =PL!D19 -> 2402.35 | E7: =PL!E19 -> 2679.95 | F7: =PL!F19 -> 3064.92 | G7: =PL!G19 -> 3384.72
A8: Add: finance costs (shown under financing) | D8: =PL!D18 -> 2300.45 | E8: =PL!E18 -> 2527.82 | F8: =PL!F18 -> 2822.75 | G8: =PL!G18 -> 3154.92
A9: Other reserve movements (OCI / adjustments) | D9: =BS!D7-BS!C7-PL!D33+PL!D37+PL!D38 -> -163.16 | E9: =BS!E7-BS!D7-PL!E33+PL!E37+PL!E38 -> -353.6 | F9: =BS!F7-BS!E7-PL!F33+PL!F37+PL!F38 -> 186.32 | G9: =BS!G7-BS!F7-PL!G33+PL!G37+PL!G38 -> 259.08 | I9: Change in reserves not explained by PAT and dividends
A10: Operating profit before working-capital changes | D10: =D6+D7+D8+D9 -> 518.2 | E10: =E6+E7+E8+E9 -> 2020.93 | F10: =F6+F7+F8+F9 -> 5592.28 | G10: =G6+G7+G8+G9 -> 8977.54
A11: (Increase)/decrease in inventories | D11: =-(BS!D34-BS!C34) -> 3056.84 | E11: =-(BS!E34-BS!D34) -> -1031.82 | F11: =-(BS!F34-BS!E34) -> -1285.32 | G11: =-(BS!G34-BS!F34) -> -2445.13
A12: (Increase)/decrease in trade receivables | D12: =-(BS!D35-BS!C35) -> 48.51 | E12: =-(BS!E35-BS!D35) -> 221.8 | F12: =-(BS!F35-BS!E35) -> -948.25 | G12: =-(BS!G35-BS!F35) -> -625.11
A13: (Increase)/decrease in short-term loans and advances | D13: =-(BS!D37-BS!C37) -> 2992.24 | E13: =-(BS!E37-BS!D37) -> 2.62 | F13: =-(BS!F37-BS!E37) -> -1.94 | G13: =-(BS!G37-BS!F37) -> 10.17
A14: (Increase)/decrease in other current assets | D14: =-(BS!D38-BS!C38) -> -3821.23 | E14: =-(BS!E38-BS!D38) -> -548.24 | F14: =-(BS!F38-BS!E38) -> -1892.3 | G14: =-(BS!G38-BS!F38) -> 414.36
A15: (Increase)/decrease in long-term loans and advances | D15: =-(BS!D31-BS!C31) -> 4057.3 | E15: =-(BS!E31-BS!D31) -> -3.57 | F15: =-(BS!F31-BS!E31) -> 2.06 | G15: =-(BS!G31-BS!F31) -> -112.52
A16: (Increase)/decrease in other non-current assets | D16: =-(BS!D32-BS!C32) -> -1693.12 | E16: =-(BS!E32-BS!D32) -> 168.6 | F16: =-(BS!F32-BS!E32) -> 161.76 | G16: =-(BS!G32-BS!F32) -> -352.05
A17: (Increase)/decrease in deferred tax assets | D17: =-(BS!D30-BS!C30) -> -1799.8 | E17: =-(BS!E30-BS!D30) -> -2206.04 | F17: =-(BS!F30-BS!E30) -> -179.43 | G17: =-(BS!G30-BS!F30) -> 1286.89
A18: Increase/(decrease) in trade payables | D18: =BS!D17-BS!C17 -> 396.33 | E18: =BS!E17-BS!D17 -> 1216.49 | F18: =BS!F17-BS!E17 -> 2321.3 | G18: =BS!G17-BS!F17 -> -282.51
A19: Increase/(decrease) in other current liabilities | D19: =BS!D18-BS!C18 -> 2448.13 | E19: =BS!E18-BS!D18 -> 1912.74 | F19: =BS!F18-BS!E18 -> 2935.22 | G19: =BS!G18-BS!F18 -> 86.86
A20: Increase/(decrease) in short-term provisions | D20: =BS!D19-BS!C19 -> 3.94 | E20: =BS!E19-BS!D19 -> 272.12 | F20: =BS!F19-BS!E19 -> -610.59 | G20: =BS!G19-BS!F19 -> 4.59
A21: Increase/(decrease) in long-term provisions | D21: =BS!D13-BS!C13 -> -433.69 | E21: =BS!E13-BS!D13 -> 322.29 | F21: =BS!F13-BS!E13 -> 379.34 | G21: =BS!G13-BS!F13 -> 322.13
A22: Increase/(decrease) in other long-term liabilities | D22: =BS!D12-BS!C12 -> 452.91 | E22: =BS!E12-BS!D12 -> -167.55 | F22: =BS!F12-BS!E12 -> -200.51 | G22: =BS!G12-BS!F12 -> 266.56
A23: Increase/(decrease) in deferred tax liabilities | D23: =BS!D11-BS!C11 -> -2395.19 | E23: =BS!E11-BS!D11 -> 0 | F23: =BS!F11-BS!E11 -> 0 | G23: =BS!G11-BS!F11 -> 0
A24: Net change in working capital and other items | D24: =D11+D12+D13+D14+D15+D16+D17+D18+D19+D20+D21+D22+D23 -> 3313.17 | E24: =E11+E12+E13+E14+E15+E16+E17+E18+E19+E20+E21+E22+E23 -> 159.44 | F24: =F11+F12+F13+F14+F15+F16+F17+F18+F19+F20+F21+F22+F23 -> 681.34 | G24: =G11+G12+G13+G14+G15+G16+G17+G18+G19+G20+G21+G22+G23 -> -1425.76
A25: NET CASH FROM OPERATING ACTIVITIES | D25: =D10+D24 -> 3831.37 | E25: =E10+E24 -> 2180.37 | F25: =F10+F24 -> 6273.62 | G25: =G10+G24 -> 7551.78
A26: B. CASH FLOW FROM INVESTING ACTIVITIES
A27: Purchase of fixed assets incl. CWIP (= change in net fixed assets + depreciation) | D27: =-(BS!D28-BS!C28+PL!D19) -> -7891.09 | E27: =-(BS!E28-BS!D28+PL!E19) -> -5387.64 | F27: =-(BS!F28-BS!E28+PL!F19) -> -6511.04 | G27: =-(BS!G28-BS!F28+PL!G19) -> -3750.45
A28: (Purchase)/sale of non-current investments | D28: =-(BS!D29-BS!C29) -> -372.68 | E28: =-(BS!E29-BS!D29) -> -103.73 | F28: =-(BS!F29-BS!E29) -> -95.82 | G28: =-(BS!G29-BS!F29) -> -93.45
A29: NET CASH USED IN INVESTING ACTIVITIES | D29: =D27+D28 -> -8263.77 | E29: =E27+E28 -> -5491.37 | F29: =F27+F28 -> -6606.86 | G29: =G27+G28 -> -3843.9
A30: C. CASH FLOW FROM FINANCING ACTIVITIES
A31: Proceeds/(repayment) of long-term borrowings | D31: =BS!D10-BS!C10 -> 3470.15 | E31: =BS!E10-BS!D10 -> 1591.77 | F31: =BS!F10-BS!E10 -> 10689.68 | G31: =BS!G10-BS!F10 -> 1025.5
A32: Proceeds/(repayment) of short-term borrowings | D32: =BS!D16-BS!C16 -> 1379.7 | E32: =BS!E16-BS!D16 -> 4238.18 | F32: =BS!F16-BS!E16 -> -7568.72 | G32: =BS!G16-BS!F16 -> -1613.1
A33: Proceeds from issue of share capital | D33: =BS!D6-BS!C6 -> 0 | E33: =BS!E6-BS!D6 -> 0 | F33: =BS!F6-BS!E6 -> 0 | G33: =BS!G6-BS!F6 -> 0
A34: Dividends paid (assumed paid in the year declared) | D34: =-PL!D37 -> -103.26 | E34: =-PL!E37 -> 0 | F34: =-PL!F37 -> 0 | G34: =-PL!G37 -> 0
A35: Tax on dividend paid | D35: =-PL!D38 -> -21.02 | E35: =-PL!E38 -> 0 | F35: =-PL!F38 -> 0 | G35: =-PL!G38 -> 0
A36: Interest / finance costs paid (assumed = P&L charge) | D36: =-PL!D18 -> -2300.45 | E36: =-PL!E18 -> -2527.82 | F36: =-PL!F18 -> -2822.75 | G36: =-PL!G18 -> -3154.92
A37: NET CASH FROM/(USED IN) FINANCING ACTIVITIES | D37: =D31+D32+D33+D34+D35+D36 -> 2425.12 | E37: =E31+E32+E33+E34+E35+E36 -> 3302.13 | F37: =F31+F32+F33+F34+F35+F36 -> 298.21 | G37: =G31+G32+G33+G34+G35+G36 -> -3742.52
A39: NET INCREASE/(DECREASE) IN CASH | D39: =D25+D29+D37 -> -2007.28 | E39: =E25+E29+E37 -> -8.87 | F39: =F25+F29+F37 -> -35.03 | G39: =G25+G29+G37 -> -34.64
A40: Cash and cash equivalents - beginning of year | D40: =BS!C36 -> 2305.24 | E40: =BS!D36 -> 297.96 | F40: =BS!E36 -> 289.09 | G40: =BS!F36 -> 254.06
A41: Cash and cash equivalents - end of year | D41: =D40+D39 -> 297.96 | E41: =E40+E39 -> 289.09 | F41: =F40+F39 -> 254.06 | G41: =G40+G39 -> 219.42
A42: Cash per balance sheet | D42: =BS!D36 -> 297.96 | E42: =BS!E36 -> 289.09 | F42: =BS!F36 -> 254.06 | G42: =BS!G36 -> 219.42
...

Sheet Ratios
A1: Steel Authority of India Ltd - Ratio Analysis
A2: All ratios are live formulas on the BS / PL / CashFlow sheets; closing-balance basis
A4: Particulars | B4: Note | C4: FY15 | D4: FY16 | E4: FY17 | F4: FY18 | G4: FY19
A5: LIQUIDITY RATIOS
A6: Current ratio (CA / CL) | C6: =BS!C39/BS!C20 -> 0.82660916 | D6: =BS!D39/BS!D20 -> 0.62553251 | E6: =BS!E39/BS!E20 -> 0.5514462 | F6: =BS!F39/BS!F20 -> 0.68288234 | G6: =BS!G39/BS!G20 -> 0.77527017
A7: Quick ratio ((CA - inventories) / CL) | C7: =(BS!C39-BS!C34)/BS!C20 -> 0.31186663 | D7: =(BS!D39-BS!D34)/BS!D20 -> 0.24606823 | E7: =(BS!E39-BS!E34)/BS!E20 -> 0.212287 | F7: =(BS!F39-BS!F34)/BS!F20 -> 0.29126862 | G7: =(BS!G39-BS!G34)/BS!G20 -> 0.30789067
A8: Cash ratio (cash / CL) | C8: =BS!C36/BS!C20 -> 0.066902363 | D8: =BS!D36/BS!D20 -> 0.0077022341 | E8: =BS!E36/BS!E20 -> 0.0062405544 | F8: =BS!F36/BS!F20 -> 0.0058536985 | G8: =BS!G36/BS!G20 -> 0.0052748413
A9: Net working capital (CA - CL), Rs. cr | C9: =BS!C39-BS!C20 -> -5974.49 | D9: =BS!D39-BS!D20 -> -14486.23 | E9: =BS!E39-BS!E20 -> -20778.99 | F9: =BS!F39-BS!F20 -> -13763.42 | G9: =BS!G39-BS!G20 -> -9348.19
A10: LEVERAGE / SOLVENCY RATIOS
A11: Total borrowings (LT + ST), Rs. cr | C11: =BS!C10+BS!C16 -> 28220.72 | D11: =BS!D10+BS!D16 -> 33070.57 | E11: =BS!E10+BS!E16 -> 38900.52 | F11: =BS!F10+BS!F16 -> 42021.48 | G11: =BS!G10+BS!G16 -> 41433.88
A12: Debt-equity ratio (total borrowings / shareholders' funds) | C12: =C11/BS!C8 -> 0.6486809 | D12: =D11/BS!D8 -> 0.84372524 | E12: =E11/BS!E8 -> 1.0802981 | F12: =F11/BS!F8 -> 1.1766217 | G12: =G11/BS!G8 -> 1.0860334
A13: Long-term debt-equity ratio | C13: =BS!C10/BS!C8 -> 0.32239124 | D13: =BS!D10/BS!D8 -> 0.44636582 | E13: =BS!E10/BS!E8 -> 0.53007438 | F13: =BS!F10/BS!F8 -> 0.83377485 | G13: =BS!G10/BS!G8 -> 0.80737595
A14: Total outside liabilities / net worth | C14: =(BS!C14+BS!C20)/BS!C8 -> 1.2831254 | D14: =(BS!D14+BS!D20)/BS!D8 -> 1.5599685 | E14: =(BS!E14+BS!E20)/BS!E8 -> 1.9586851 | F14: =(BS!F14+BS!F20)/BS!F8 -> 2.1973695 | G14: =(BS!G14+BS!G20)/BS!G8 -> 2.0519774
A15: Debt / (debt + equity) | C15: =C11/(C11+BS!C8) -> 0.39345449 | D15: =D11/(D11+BS!D8) -> 0.45761983 | E15: =E11/(E11+BS!E8) -> 0.51929967 | F15: =F11/(F11+BS!F8) -> 0.54057244 | G15: =G11/(G11+BS!G8) -> 0.52062129
A16: Interest cover ((PBT before exceptional + finance cost) / finance cost) | C16: =(PL!C22+PL!C18)/PL!C18 -> 2.6827737 | D16: =(PL!D22+PL!D18)/PL!D18 -> -2.0461431 | E16: =(PL!E22+PL!E18)/PL!E18 -> -0.83324762 | F16: =(PL!F22+PL!F18)/PL!F18 -> 0.72177132 | G16: =(PL!G22+PL!G18)/PL!G18 -> 2.1814214
A17: PROFITABILITY RATIOS
A18: Operating profit / EBITDA = total op. revenue - (total expenses - finance cost - D&A), Rs. cr | C18: =PL!C10-(PL!C21-PL!C18-PL!C19) -> 4653.87 | D18: =PL!D10-(PL!D21-PL!D18-PL!D19) -> -2899.37 | E18: =PL!E10-(PL!E21-PL!E18-PL!E19) -> 38.04 | F18: =PL!F10-(PL!F21-PL!F18-PL!F19) -> 4617.85 | G18: =PL!G10-(PL!G21-PL!G18-PL!G19) -> 9734.11
A19: Operating profit margin (EBITDA / total operating revenue) | C19: =C18/PL!C10 -> 0.10181121 | D19: =D18/PL!D10 -> -0.074244057 | E19: =E18/PL!E10 -> 0.00085574663 | F19: =F18/PL!F10 -> 0.080228866 | G19: =G18/PL!G10 -> 0.14535614
A20: EBIT = EBITDA - D&A, Rs. cr | C20: =C18-PL!C19 -> 2880.59 | D20: =D18-PL!D19 -> -5301.72 | E20: =E18-PL!E19 -> -2641.91 | F20: =F18-PL!F19 -> 1552.93 | G20: =G18-PL!G19 -> 6349.39
A21: EBIT margin | C21: =C20/PL!C10 -> 0.063017739 | D21: =D20/PL!D10 -> -0.13576094 | E21: =E20/PL!E10 -> -0.059432323 | F21: =F20/PL!F10 -> 0.026980048 | G21: =G20/PL!G10 -> 0.094813275
A22: Gross profit margin ((op. revenue - net material cost) / op. revenue) | C22: =(PL!C10-PL!C14-PL!C15-PL!C16)/PL!C10 -> 0.62557497 | D22: =(PL!D10-PL!D14-PL!D15-PL!D16)/PL!D10 -> 0.5468633 | E22: =(PL!E10-PL!E14-PL!E15-PL!E16)/PL!E10 -> 0.52204324 | F22: =(PL!F10-PL!F14-PL!F15-PL!F16)/PL!F10 -> 0.51676435 | G22: =(PL!G10-PL!G14-PL!G15-PL!G16)/PL!G10 -> 0.55837721
A23: Net profit margin (PAT / total operating revenue) | C23: =PL!C33/PL!C10 -> 0.045780886 | D23: =PL!D33/PL!D10 -> -0.10297686 | E23: =PL!E33/PL!E10 -> -0.063736477 | F23: =PL!F33/PL!F10 -> -0.0083690564 | G23: =PL!G33/PL!G10 -> 0.032535576
A24: Return on net worth (PAT / shareholders' funds) | C24: =PL!C33/BS!C8 -> 0.0481023 | D24: =PL!D33/BS!D8 -> -0.10259849 | E24: =PL!E33/BS!E8 -> -0.07868131 | F24: =PL!F33/BS!F8 -> -0.013488113 | G24: =PL!G33/BS!G8 -> 0.057109576
A25: Return on capital employed ((PBT before exc. + finance cost) / (total assets - CL)) | C25: =(PL!C22+PL!C18)/(BS!C40-BS!C20) -> 0.060141276 | D25: =(PL!D22+PL!D18)/(BS!D40-BS!D20) -> -0.076344501 | E25: =(PL!E22+PL!E18)/(BS!E40-BS!E20) -> -0.034979621 | F25: =(PL!F22+PL!F18)/(BS!F40-BS!F20) -> 0.028781359 | G25: =(PL!G22+PL!G18)/(BS!G40-BS!G20) -> 0.091958647
A26: Return on assets (PAT / total assets) | C26: =PL!C33/BS!C40 -> 0.021068619 | D26: =PL!D33/BS!D40 -> -0.040078026 | E26: =PL!E33/BS!E40 -> -0.026593337 | F26: =PL!F33/BS!F40 -> -0.0042185029 | G26: =PL!G33/BS!G40 -> 0.018712319
A27: PER-SHARE RATIOS (Rs.)
A28: Earnings per share | C28: =PL!C36 -> 5.0663716 | D28: =PL!D36 -> -9.7358935 | E28: =PL!E36 -> -6.859265 | F28: =PL!F36 -> -1.1662184 | G28: =PL!G36 -> 5.2749163
A29: Book value per share | C29: =BS!C8/(BS!C6/Assumptions!$C$6) -> 105.32493 | D29: =BS!D8/(BS!D6/Assumptions!$C$6) -> 94.893149 | E29: =BS!E8/(BS!E6/Assumptions!$C$6) -> 87.17782 | F29: =BS!F8/(BS!F6/Assumptions!$C$6) -> 86.462682 | G29: =BS!G8/(BS!G6/Assumptions!$C$6) -> 92.36483
A30: Dividend per share | C30: =PL!C37/(BS!C6/Assumptions!$C$6) -> 1.9999855 | D30: =PL!D37/(BS!D6/Assumptions!$C$6) -> 0.24999213 | E30: =PL!E37/(BS!E6/Assumptions!$C$6) -> 0 | F30: =PL!F37/(BS!F6/Assumptions!$C$6) -> 0 | G30: =PL!G37/(BS!G6/Assumptions!$C$6) -> 0
A31: Dividend payout ratio (dividend / PAT) | C31: =IF(PL!C33>0,PL!C37/PL!C33,0) -> 0.39475696 | D31: =IF(PL!D33>0,PL!D37/PL!D33,0) -> 0 | E31: =IF(PL!E33>0,PL!E37/PL!E33,0) -> 0 | F31: =IF(PL!F33>0,PL!F37/PL!F33,0) -> 0 | G31: =IF(PL!G33>0,PL!G37/PL!G33,0) -> 0
A32: EFFICIENCY / TURNOVER RATIOS
A33: Inventory turnover (op. revenue / closing inventory) | C33: =PL!C10/BS!C34 -> 2.5772342 | D33: =PL!D10/BS!D34 -> 2.660295 | E33: =PL!E10/BS!E34 -> 2.8293183 | F33: =PL!F10/BS!F34 -> 3.3864551 | G33: =PL!G10/BS!G34 -> 3.4445015
A34: Inventory days | C34: =365/C33 -> 141.62469 | D34: =365/D33 -> 137.20283 | E34: =365/E33 -> 129.00634 | F34: =365/F33 -> 107.78232 | G34: =365/G33 -> 105.96599
A35: Debtors turnover (op. revenue / closing receivables) | C35: =PL!C10/BS!C35 -> 14.32042 | D35: =PL!D10/BS!D35 -> 12.423097 | E35: =PL!E10/BS!E35 -> 15.214622 | F35: =PL!F10/BS!F35 -> 14.873218 | G35: =PL!G10/BS!G35 -> 14.898012
A36: Debtors days | C36: =365/C35 -> 25.48808 | D36: =365/D35 -> 29.380758 | E36: =365/E35 -> 23.99008 | F36: =365/F35 -> 24.540756 | G36: =365/G35 -> 24.499913
A37: Creditors days (payables / op. revenue x 365) | C37: =BS!C17/PL!C10*365 -> 28.796899 | D37: =BS!D17/PL!D10*365 -> 37.411493 | E37: =BS!E17/PL!E10*365 -> 42.854999 | F37: =BS!F17/PL!F10*365 -> 47.817167 | G37: =BS!G17/PL!G10*365 -> 39.559098
A38: Cash conversion cycle (inventory days + debtors days - creditors days) | C38: =C34+C36-C37 -> 138.31587 | D38: =D34+D36-D37 -> 129.17209 | E38: =E34+E36-E37 -> 110.14142 | F38: =F34+F36-F37 -> 84.505912 | G38: =G34+G36-G37 -> 90.906801
A39: Fixed assets turnover (op. revenue / fixed assets) | C39: =PL!C10/BS!C28 -> 0.69932194 | D39: =PL!D10/BS!D28 -> 0.55116631 | E39: =PL!E10/BS!E28 -> 0.60429432 | F39: =PL!F10/BS!F28 -> 0.74744471 | G39: =PL!G10/BS!G28 -> 0.86551589
A40: Total assets turnover (op. revenue / total assets) | C40: =PL!C10/BS!C40 -> 0.46020558 | D40: =PL!D10/BS!D40 -> 0.38919449 | E40: =PL!E10/BS!E40 -> 0.41723889 | F40: =PL!F10/BS!F40 -> 0.50405956 | G40: =PL!G10/BS!G40 -> 0.57513411
A41: DUPONT ANALYSIS (ROE = net margin x asset turnover x equity multiplier)
...

Sheet Assumptions
A1: Forecast Assumptions
A2: Rs. crore | blue/yellow cells are inputs - change them and the whole model recalculates
C3: Actual | H3: Forecast
A4: Particulars | B4: Note | C4: FY15 | D4: FY16 | E4: FY17 | F4: FY18 | G4: FY19 | H4: FY20E | I4: FY21E | J4: FY22E | K4: FY23E | L4: FY24E
A5: GENERAL
A6: Face value per equity share (Rs.) | C6: 10
A7: INCOME STATEMENT DRIVERS (hist. = computed from data; forecast = input)
A8: Total operating revenue growth | D8: =PL!D10/PL!C10-1 -> -0.14567461 | E8: =PL!E10/PL!D10-1 -> 0.13829117 | F8: =PL!F10/PL!E10-1 -> 0.29483328 | G8: =PL!G10/PL!F10-1 -> 0.16346598 | H8: 0.05 | I8: 0.07 | J8: 0.07 | K8: 0.06 | L8: 0.06
A9: Net material cost (cost of materials + purchases + inventory change) % of op. revenue | C9: =(PL!C14+PL!C15+PL!C16)/PL!C10 -> 0.37442503 | D9: =(PL!D14+PL!D15+PL!D16)/PL!D10 -> 0.4531367 | E9: =(PL!E14+PL!E15+PL!E16)/PL!E10 -> 0.47795676 | F9: =(PL!F14+PL!F15+PL!F16)/PL!F10 -> 0.48323565 | G9: =(PL!G14+PL!G15+PL!G16)/PL!G10 -> 0.44162279 | H9: 0.46 | I9: 0.46 | J9: 0.46 | K9: 0.46 | L9: 0.46
A10: Employee cost % of op. revenue | C10: =PL!C17/PL!C10 -> 0.21299855 | D10: =PL!D17/PL!D10 -> 0.24877087 | E10: =PL!E17/PL!E10 -> 0.2012901 | F10: =PL!F17/PL!F10 -> 0.15375794 | G10: =PL!G17/PL!G10 -> 0.13186046 | H10: 0.13 | I10: 0.128 | J10: 0.126 | K10: 0.124 | L10: 0.122
A11: Other expenses % of op. revenue | C11: =PL!C20/PL!C10 -> 0.31076521 | D11: =PL!D20/PL!D10 -> 0.37233649 | E11: =PL!E20/PL!E10 -> 0.31989739 | F11: =PL!F20/PL!F10 -> 0.28277754 | G11: =PL!G20/PL!G10 -> 0.28116061 | H11: 0.28 | I11: 0.28 | J11: 0.28 | K11: 0.28 | L11: 0.28
A12: Other income % of op. revenue | C12: =PL!C11/PL!C10 -> 0.022331275 | D12: =PL!D11/PL!D10 -> 0.015227692 | E12: =PL!E11/PL!E10 -> 0.012049066 | F12: =PL!F11/PL!F10 -> 0.0084166602 | G12: =PL!G11/PL!G10 -> 0.0079564193 | H12: 0.008 | I12: 0.008 | J12: 0.008 | K12: 0.008 | L12: 0.008
A13: Depreciation % of opening net fixed assets | D13: =PL!D19/BS!C28 -> 0.03675317 | E13: =PL!E19/BS!D28 -> 0.037823996 | F13: =PL!F19/BS!E28 -> 0.041665092 | G13: =PL!G19/BS!F28 -> 0.043953418 | H13: 0.044 | I13: 0.044 | J13: 0.044 | K13: 0.044 | L13: 0.044
A14: Interest rate on opening total borrowings | D14: =PL!D18/(BS!C10+BS!C16) -> 0.081516347 | E14: =PL!E18/(BS!D10+BS!D16) -> 0.076437146 | F14: =PL!F18/(BS!E10+BS!E16) -> 0.072563297 | G14: =PL!G18/(BS!F10+BS!F16) -> 0.075078745 | H14: 0.075 | I14: 0.075 | J14: 0.075 | K14: 0.075 | L14: 0.075
A15: Tax rate (hist. = effective rate where PBT > 0) | C15: =IF(PL!C24>0,PL!C30/PL!C24,"n.m.") -> 0.1087923 | D15: =IF(PL!D24>0,PL!D30/PL!D24,"n.m.") -> n.m. | E15: =IF(PL!E24>0,PL!E30/PL!E24,"n.m.") -> n.m. | F15: =IF(PL!F24>0,PL!F30/PL!F24,"n.m.") -> n.m. | G15: =IF(PL!G24>0,PL!G30/PL!G24,"n.m.") -> 0.34724631 | H15: 0.2517 | I15: 0.2517 | J15: 0.2517 | K15: 0.2517 | L15: 0.2517 | N15: 25.17% = Sec 115BAA rate; use 34.94% if old regime applies
A16: Exceptional items (Rs. cr) | C16: =PL!C23 -> 0 | D16: =PL!D23 -> 0 | E16: =PL!E23 -> -216.74 | F16: =PL!F23 -> 26.43 | G16: =PL!G23 -> -389.4 | H16: 0 | I16: 0 | J16: 0 | K16: 0 | L16: 0
A17: Prior-period items (Rs. cr) | C17: =PL!C32 -> -88.23 | D17: =PL!D32 -> 0 | E17: =PL!E32 -> 0 | F17: =PL!F32 -> 0 | G17: =PL!G32 -> 0 | H17: 0 | I17: 0 | J17: 0 | K17: 0 | L17: 0
A18: Dividend payout (% of PAT) | C18: =IF(PL!C33>0,PL!C37/PL!C33,0) -> 0.39475696 | D18: =IF(PL!D33>0,PL!D37/PL!D33,0) -> 0 | E18: =IF(PL!E33>0,PL!E37/PL!E33,0) -> 0 | F18: =IF(PL!F33>0,PL!F37/PL!F33,0) -> 0 | G18: =IF(PL!G33>0,PL!G37/PL!G33,0) -> 0 | H18: 0.1 | I18: 0.15 | J18: 0.2 | K18: 0.2 | L18: 0.2
A19: Dividend distribution tax rate (abolished w.e.f. 1-Apr-2020) | C19: =IF(PL!C37>0,PL!C38/PL!C37,0) -> 0.19947948 | D19: =IF(PL!D37>0,PL!D38/PL!D37,0) -> 0.20356382 | E19: =IF(PL!E37>0,PL!E38/PL!E37,0) -> 0 | F19: =IF(PL!F37>0,PL!F38/PL!F37,0) -> 0 | G19: =IF(PL!G37>0,PL!G38/PL!G37,0) -> 0 | H19: 0.2056 | I19: 0 | J19: 0 | K19: 0 | L19: 0
A20: BALANCE SHEET DRIVERS
A21: Inventory days (on op. revenue) | C21: =BS!C34/PL!C10*365 -> 141.62469 | D21: =BS!D34/PL!D10*365 -> 137.20283 | E21: =BS!E34/PL!E10*365 -> 129.00634 | F21: =BS!F34/PL!F10*365 -> 107.78232 | G21: =BS!G34/PL!G10*365 -> 105.96599 | H21: 105 | I21: 105 | J21: 105 | K21: 105 | L21: 105
A22: Receivable days (on op. revenue) | C22: =BS!C35/PL!C10*365 -> 25.48808 | D22: =BS!D35/PL!D10*365 -> 29.380758 | E22: =BS!E35/PL!E10*365 -> 23.99008 | F22: =BS!F35/PL!F10*365 -> 24.540756 | G22: =BS!G35/PL!G10*365 -> 24.499913 | H22: 24 | I22: 24 | J22: 24 | K22: 24 | L22: 24
A23: Payable days (on op. revenue) | C23: =BS!C17/PL!C10*365 -> 28.796899 | D23: =BS!D17/PL!D10*365 -> 37.411493 | E23: =BS!E17/PL!E10*365 -> 42.854999 | F23: =BS!F17/PL!F10*365 -> 47.817167 | G23: =BS!G17/PL!G10*365 -> 39.559098 | H23: 40 | I23: 40 | J23: 40 | K23: 40 | L23: 40
A24: Other current assets % of op. revenue | C24: =BS!C38/PL!C10 -> 0.047961334 | D24: =BS!D38/PL!D10 -> 0.15398951 | E24: =BS!E38/PL!E10 -> 0.14761449 | F24: =BS!F38/PL!F10 -> 0.14687884 | G24: =BS!G38/PL!G10 -> 0.12005499 | H24: 0.12 | I24: 0.12 | J24: 0.12 | K24: 0.12 | L24: 0.12
A25: Other current liabilities % of op. revenue | C25: =BS!C18/PL!C10 -> 0.30663511 | D25: =BS!D18/PL!D10 -> 0.42160992 | E25: =BS!E18/PL!E10 -> 0.41341741 | F25: =BS!F18/PL!F10 -> 0.3702778 | G25: =BS!G18/PL!G10 -> 0.31955114 | H25: 0.32 | I25: 0.32 | J25: 0.32 | K25: 0.32 | L25: 0.32
A26: CAPEX AND FINANCING (Rs. cr)
A27: Capital expenditure incl. CWIP | D27: =-CashFlow!D27 -> 7891.09 | E27: =-CashFlow!E27 -> 5387.64 | F27: =-CashFlow!F27 -> 6511.04 | G27: =-CashFlow!G27 -> 3750.45 | H27: 3500 | I27: 3200 | J27: 3000 | K27: 3000 | L27: 3000
A28: New long-term borrowings | H28: 0 | I28: 0 | J28: 0 | K28: 0 | L28: 0
A29: Repayment of long-term borrowings | H29: 1500 | I29: 1500 | J29: 1500 | K29: 1500 | L29: 1500
A30: Net change in short-term borrowings | D30: =BS!D16-BS!C16 -> 1379.7 | E30: =BS!E16-BS!D16 -> 4238.18 | F30: =BS!F16-BS!E16 -> -7568.72 | G30: =BS!G16-BS!F16 -> -1613.1 | H30: 0 | I30: 0 | J30: 0 | K30: 0 | L30: 0
A32: HELD CONSTANT AT FY19 LEVEL IN THE FORECAST
A33: Share capital, DTL/DTA, other long-term liabilities, long-term provisions, short-term provisions,
A34: non-current investments, long-term and short-term loans & advances, other non-current assets.

Sheet Model
A1: Three-Statement Financial Model FY20E-FY24E
A2: Rs. crore | history links to the data sheets; forecast driven by the Assumptions sheet
C3: Actual | H3: Forecast
A4: Particulars | B4: Note | C4: FY15 | D4: FY16 | E4: FY17 | F4: FY18 | G4: FY19 | H4: FY20E | I4: FY21E | J4: FY22E | K4: FY23E | L4: FY24E
A5: INCOME STATEMENT (Rs. crore)
A6: Total operating revenue | C6: =PL!C10 -> 45710.78 | D6: =PL!D10 -> 39051.88 | E6: =PL!E10 -> 44452.41 | F6: =PL!F10 -> 57558.46 | G6: =PL!G10 -> 66967.31 | H6: =G6*(1+Assumptions!H8) -> 70315.675 | I6: =H6*(1+Assumptions!I8) -> 75237.773 | J6: =I6*(1+Assumptions!J8) -> 80504.417 | K6: =J6*(1+Assumptions!K8) -> 85334.682 | L6: =K6*(1+Assumptions!L8) -> 90454.763
A7: growth % | D7: =D6/C6-1 -> -0.14567461 | E7: =E6/D6-1 -> 0.13829117 | F7: =F6/E6-1 -> 0.29483328 | G7: =G6/F6-1 -> 0.16346598 | H7: =H6/G6-1 -> 0.05 | I7: =I6/H6-1 -> 0.07 | J7: =J6/I6-1 -> 0.07 | K7: =K6/J6-1 -> 0.06 | L7: =L6/K6-1 -> 0.06
A8: Net material cost | C8: =PL!C14+PL!C15+PL!C16 -> 17115.26 | D8: =PL!D14+PL!D15+PL!D16 -> 17695.84 | E8: =PL!E14+PL!E15+PL!E16 -> 21246.33 | F8: =PL!F14+PL!F15+PL!F16 -> 27814.3 | G8: =PL!G14+PL!G15+PL!G16 -> 29574.29 | H8: =H6*Assumptions!H9 -> 32345.211 | I8: =I6*Assumptions!I9 -> 34609.375 | J8: =J6*Assumptions!J9 -> 37032.032 | K8: =K6*Assumptions!K9 -> 39253.954 | L8: =L6*Assumptions!L9 -> 41609.191
A9: Employee benefit expenses | C9: =PL!C17 -> 9736.33 | D9: =PL!D17 -> 9714.97 | E9: =PL!E17 -> 8947.83 | F9: =PL!F17 -> 8850.07 | G9: =PL!G17 -> 8830.34 | H9: =H6*Assumptions!H10 -> 9141.0378 | I9: =I6*Assumptions!I10 -> 9630.4349 | J9: =J6*Assumptions!J10 -> 10143.557 | K9: =K6*Assumptions!K10 -> 10581.501 | L9: =L6*Assumptions!L10 -> 11035.481
A10: Other expenses | C10: =PL!C20 -> 14205.32 | D10: =PL!D20 -> 14540.44 | E10: =PL!E20 -> 14220.21 | F10: =PL!F20 -> 16276.24 | G10: =PL!G20 -> 18828.57 | H10: =H6*Assumptions!H11 -> 19688.389 | I10: =I6*Assumptions!I11 -> 21066.576 | J10: =J6*Assumptions!J11 -> 22541.237 | K10: =K6*Assumptions!K11 -> 23893.711 | L10: =L6*Assumptions!L11 -> 25327.334
A11: EBITDA | C11: =C6-C8-C9-C10 -> 4653.87 | D11: =D6-D8-D9-D10 -> -2899.37 | E11: =E6-E8-E9-E10 -> 38.04 | F11: =F6-F8-F9-F10 -> 4617.85 | G11: =G6-G8-G9-G10 -> 9734.11 | H11: =H6-H8-H9-H10 -> 9141.0378 | I11: =I6-I8-I9-I10 -> 9931.386 | J11: =J6-J8-J9-J10 -> 10787.592 | ... L11: =L6-L8-L9-L10 -> 12482.757
A12: EBITDA margin | C12: =C11/C6 -> 0.10181121 | D12: =D11/D6 -> -0.074244057 | E12: =E11/E6 -> 0.00085574663 | F12: =F11/F6 -> 0.080228866 | G12: =G11/G6 -> 0.14535614 | H12: =H11/H6 -> 0.13 | I12: =I11/I6 -> 0.132 | J12: =J11/J6 -> 0.134 | ... L12: =L11/L6 -> 0.138
A13: Depreciation and amortisation | C13: =PL!C19 -> 1773.28 | D13: =PL!D19 -> 2402.35 | E13: =PL!E19 -> 2679.95 | F13: =PL!F19 -> 3064.92 | G13: =PL!G19 -> 3384.72 | H13: =G41*Assumptions!H13 -> 3404.3992 | I13: =H41*Assumptions!I13 -> 3408.6057 | J13: =I41*Assumptions!J13 -> 3399.427 | K13: =J41*Assumptions!K13 -> 3381.8522 | L13: =K41*Assumptions!L13 -> 3365.0507
A14: EBIT | C14: =C11-C13 -> 2880.59 | D14: =D11-D13 -> -5301.72 | E14: =E11-E13 -> -2641.91 | F14: =F11-F13 -> 1552.93 | G14: =G11-G13 -> 6349.39 | H14: =H11-H13 -> 5736.6386 | I14: =I11-I13 -> 6522.7803 | J14: =J11-J13 -> 7388.1648 | ... L14: =L11-L13 -> 9117.7065
A15: Other income | C15: =PL!C11 -> 1020.78 | D15: =PL!D11 -> 594.67 | E15: =PL!E11 -> 535.61 | F15: =PL!F11 -> 484.45 | G15: =PL!G11 -> 532.82 | H15: =H6*Assumptions!H12 -> 562.5254 | I15: =I6*Assumptions!I12 -> 601.90218 | J15: =J6*Assumptions!J12 -> 644.03534 | K15: =K6*Assumptions!K12 -> 682.67746 | L15: =L6*Assumptions!L12 -> 723.6381
A16: Finance costs | C16: =PL!C18 -> 1454.23 | D16: =PL!D18 -> 2300.45 | E16: =PL!E18 -> 2527.82 | F16: =PL!F18 -> 2822.75 | G16: =PL!G18 -> 3154.92 | H16: =(G32+G36)*Assumptions!H14 -> 3107.541 | I16: =(H32+H36)*Assumptions!I14 -> 2995.041 | J16: =(I32+I36)*Assumptions!J14 -> 2882.541 | K16: =(J32+J36)*Assumptions!K14 -> 2770.041 | L16: =(K32+K36)*Assumptions!L14 -> 2657.541
A17: Exceptional items | C17: =PL!C23 -> 0 | D17: =PL!D23 -> 0 | E17: =PL!E23 -> -216.74 | F17: =PL!F23 -> 26.43 | G17: =PL!G23 -> -389.4 | H17: =Assumptions!H16 -> 0 | I17: =Assumptions!I16 -> 0 | J17: =Assumptions!J16 -> 0 | K17: =Assumptions!K16 -> 0 | L17: =Assumptions!L16 -> 0
A18: Profit before tax | C18: =C14+C15-C16+C17 -> 2447.14 | D18: =D14+D15-D16+D17 -> -7007.5 | E18: =E14+E15-E16+E17 -> -4850.86 | F18: =F14+F15-F16+F17 -> -758.94 | G18: =G14+G15-G16+G17 -> 3337.89 | H18: =H14+H15-H16+H17 -> 3191.623 | I18: =I14+I15-I16+I17 -> 4129.6415 | J18: =J14+J15-J16+J17 -> 5149.6592 | ... L18: =L14+L15-L16+L17 -> 7183.8036
A19: Tax expense | C19: =PL!C30 -> 266.23 | D19: =PL!D30 -> -2986.06 | E19: =PL!E30 -> -2017.62 | F19: =PL!F30 -> -277.23 | G19: =PL!G30 -> 1159.07 | H19: =MAX(H18,0)*Assumptions!H15 -> 803.3315 | I19: =MAX(I18,0)*Assumptions!I15 -> 1039.4308 | J19: =MAX(J18,0)*Assumptions!J15 -> 1296.1692 | K19: =MAX(K18,0)*Assumptions!K15 -> 1544.507 | L19: =MAX(L18,0)*Assumptions!L15 -> 1808.1634
A20: Prior-period items | C20: =PL!C32 -> -88.23 | D20: =PL!D32 -> 0 | E20: =PL!E32 -> 0 | F20: =PL!F32 -> 0 | G20: =PL!G32 -> 0 | H20: =Assumptions!H17 -> 0 | I20: =Assumptions!I17 -> 0 | J20: =Assumptions!J17 -> 0 | K20: =Assumptions!K17 -> 0 | L20: =Assumptions!L17 -> 0
A21: Profit after tax | C21: =C18-C19+C20 -> 2092.68 | D21: =D18-D19+D20 -> -4021.44 | E21: =E18-E19+E20 -> -2833.24 | F21: =F18-F19+F20 -> -481.71 | G21: =G18-G19+G20 -> 2178.82 | H21: =H18-H19+H20 -> 2388.2915 | I21: =I18-I19+I20 -> 3090.2107 | J21: =J18-J19+J20 -> 3853.49 | ... L21: =L18-L19+L20 -> 5375.6403
A22: PAT margin | C22: =C21/C6 -> 0.045780886 | D22: =D21/D6 -> -0.10297686 | E22: =E21/E6 -> -0.063736477 | F22: =F21/F6 -> -0.0083690564 | G22: =G21/G6 -> 0.032535576 | H22: =H21/H6 -> 0.033965278 | I22: =I21/I6 -> 0.041072597 | J22: =J21/J6 -> 0.047866814 | ... L22: =L21/L6 -> 0.059429046
A23: Dividend | C23: =PL!C37 -> 826.1 | D23: =PL!D37 -> 103.26 | E23: =PL!E37 -> 0 | F23: =PL!F37 -> 0 | G23: =PL!G37 -> 0 | H23: =MAX(H21,0)*Assumptions!H18 -> 238.82915 | I23: =MAX(I21,0)*Assumptions!I18 -> 463.53161 | J23: =MAX(J21,0)*Assumptions!J18 -> 770.69799 | K23: =MAX(K21,0)*Assumptions!K18 -> 918.3588 | L23: =MAX(L21,0)*Assumptions!L18 -> 1075.1281
A24: Tax on dividend | C24: =PL!C38 -> 164.79 | D24: =PL!D38 -> 21.02 | E24: =PL!E38 -> 0 | F24: =PL!F38 -> 0 | G24: =PL!G38 -> 0 | H24: =H23*Assumptions!H19 -> 49.103273 | I24: =I23*Assumptions!I19 -> 0 | J24: =J23*Assumptions!J19 -> 0 | K24: =K23*Assumptions!K19 -> 0 | L24: =L23*Assumptions!L19 -> 0
A25: EPS (Rs.) | C25: =C21/(C29/Assumptions!$C$6) -> 5.0663716 | D25: =D21/(D29/Assumptions!$C$6) -> -9.7358935 | E25: =E21/(E29/Assumptions!$C$6) -> -6.859265 | F25: =F21/(F29/Assumptions!$C$6) -> -1.1662184 | G25: =G21/(G29/Assumptions!$C$6) -> 5.2749163 | H25: =H21/(H29/Assumptions!$C$6) -> 5.7820461 | I25: =I21/(I29/Assumptions!$C$6) -> 7.4813904 | J25: =J21/(J29/Assumptions!$C$6) -> 9.3292869 | ... L25: =L21/(L29/Assumptions!$C$6) -> 13.014408
A26: Check: model PAT - reported PAT (history) | C26: =ROUND(C21-PL!C33,2) -> 0 | D26: =ROUND(D21-PL!D33,2) -> 0 | E26: =ROUND(E21-PL!E33,2) -> 0 | F26: =ROUND(F21-PL!F33,2) -> 0 | G26: =ROUND(G21-PL!G33,2) -> 0
A28: BALANCE SHEET (Rs. crore)
A29: Equity share capital | C29: =BS!C6 -> 4130.53 | D29: =BS!D6 -> 4130.53 | E29: =BS!E6 -> 4130.53 | F29: =BS!F6 -> 4130.53 | G29: =BS!G6 -> 4130.53 | H29: =G29 -> 4130.53 | I29: =H29 -> 4130.53 | J29: =I29 -> 4130.53 | K29: =J29 -> 4130.53 | L29: =K29 -> 4130.53
A30: Reserves and surplus | C30: =BS!C7 -> 39374.25 | D30: =BS!D7 -> 35065.37 | E30: =BS!E7 -> 31878.53 | F30: =BS!F7 -> 31583.14 | G30: =BS!G7 -> 34021.04 | H30: =G30+H21-H23-H24 -> 36121.399 | I30: =H30+I21-I23-I24 -> 38748.078 | J30: =I30+J21-J23-J24 -> 41830.87 | K30: =J30+K21-K23-K24 -> 45504.305 | L30: =K30+L21-L23-L24 -> 49804.818
A31: Total shareholders' funds | C31: =C29+C30 -> 43504.78 | D31: =D29+D30 -> 39195.9 | E31: =E29+E30 -> 36009.06 | F31: =F29+F30 -> 35713.67 | G31: =G29+G30 -> 38151.57 | H31: =H29+H30 -> 40251.929 | I31: =I29+I30 -> 42878.608 | J31: =J29+J30 -> 45961.4 | ... L31: =L29+L30 -> 53935.348
A32: Long-term borrowings | C32: =BS!C10 -> 14025.56 | D32: =BS!D10 -> 17495.71 | E32: =BS!E10 -> 19087.48 | F32: =BS!F10 -> 29777.16 | G32: =BS!G10 -> 30802.66 | H32: =G32+Assumptions!H28-Assumptions!H29 -> 29302.66 | I32: =H32+Assumptions!I28-Assumptions!I29 -> 27802.66 | J32: =I32+Assumptions!J28-Assumptions!J29 -> 26302.66 | K32: =J32+Assumptions!K28-Assumptions!K29 -> 24802.66 | L32: =K32+Assumptions!L28-Assumptions!L29 -> 23302.66
A33: Deferred tax liabilities (net) | C33: =BS!C11 -> 2395.19 | D33: =BS!D11 -> 0 | E33: =BS!E11 -> 0 | F33: =BS!F11 -> 0 | G33: =BS!G11 -> 0 | H33: =G33 -> 0 | I33: =H33 -> 0 | J33: =I33 -> 0 | K33: =J33 -> 0 | L33: =K33 -> 0
A34: Other long-term liabilities | C34: =BS!C12 -> 1239.22 | D34: =BS!D12 -> 1692.13 | E34: =BS!E12 -> 1524.58 | F34: =BS!F12 -> 1324.07 | G34: =BS!G12 -> 1590.63 | H34: =G34 -> 1590.63 | I34: =H34 -> 1590.63 | J34: =I34 -> 1590.63 | K34: =J34 -> 1590.63 | L34: =K34 -> 1590.63
A35: Long-term provisions | C35: =BS!C13 -> 3705.34 | D35: =BS!D13 -> 3271.65 | E35: =BS!E13 -> 3593.94 | F35: =BS!F13 -> 3973.28 | G35: =BS!G13 -> 4295.41 | H35: =G35 -> 4295.41 | I35: =H35 -> 4295.41 | J35: =I35 -> 4295.41 | K35: =J35 -> 4295.41 | L35: =K35 -> 4295.41
A36: Short-term borrowings | C36: =BS!C16 -> 14195.16 | D36: =BS!D16 -> 15574.86 | E36: =BS!E16 -> 19813.04 | F36: =BS!F16 -> 12244.32 | G36: =BS!G16 -> 10631.22 | H36: =G36+Assumptions!H30 -> 10631.22 | I36: =H36+Assumptions!I30 -> 10631.22 | J36: =I36+Assumptions!J30 -> 10631.22 | K36: =J36+Assumptions!K30 -> 10631.22 | L36: =K36+Assumptions!L30 -> 10631.22
A37: Trade payables | C37: =BS!C17 -> 3606.38 | D37: =BS!D17 -> 4002.71 | E37: =BS!E17 -> 5219.2 | F37: =BS!F17 -> 7540.5 | G37: =BS!G17 -> 7257.99 | H37: =H6*Assumptions!H23/365 -> 7705.8275 | I37: =I6*Assumptions!I23/365 -> 8245.2354 | J37: =J6*Assumptions!J23/365 -> 8822.4018 | K37: =K6*Assumptions!K23/365 -> 9351.746 | L37: =L6*Assumptions!L23/365 -> 9912.8507
A38: Other current liabilities | C38: =BS!C18 -> 14016.53 | D38: =BS!D18 -> 16464.66 | E38: =BS!E18 -> 18377.4 | F38: =BS!F18 -> 21312.62 | G38: =BS!G18 -> 21399.48 | H38: =H6*Assumptions!H25 -> 22501.016 | I38: =I6*Assumptions!I25 -> 24076.087 | J38: =J6*Assumptions!J25 -> 25761.413 | K38: =K6*Assumptions!K25 -> 27307.098 | L38: =L6*Assumptions!L25 -> 28945.524
A39: Short-term provisions | C39: =BS!C19 -> 2638.71 | D39: =BS!D19 -> 2642.65 | E39: =BS!E19 -> 2914.77 | F39: =BS!F19 -> 2304.18 | G39: =BS!G19 -> 2308.77 | H39: =G39 -> 2308.77 | I39: =H39 -> 2308.77 | J39: =I39 -> 2308.77 | K39: =J39 -> 2308.77 | L39: =K39 -> 2308.77
A40: TOTAL CAPITAL AND LIABILITIES | C40: =C31+C32+C33+C34+C35+C36+C37+C38+C39 -> 99326.87 | D40: =D31+D32+D33+D34+D35+D36+D37+D38+D39 -> 100340.27 | E40: =E31+E32+E33+E34+E35+E36+E37+E38+E39 -> 106539.47 | F40: =F31+F32+F33+F34+F35+F36+F37+F38+F39 -> 114189.8 | G40: =G31+G32+G33+G34+G35+G36+G37+G38+G39 -> 116437.73 | H40: =H31+H32+H33+H34+H35+H36+H37+H38+H39 -> 118587.46 | I40: =I31+I32+I33+I34+I35+I36+I37+I38+I39 -> 121828.62 | J40: =J31+J32+J33+J34+J35+J36+J37+J38+J39 -> 125673.91 | ... L40: =L31+L32+L33+L34+L35+L36+L37+L38+L39 -> 134922.41
A41: Net fixed assets incl. CWIP | C41: =BS!C28 -> 65364.43 | D41: =BS!D28 -> 70853.17 | E41: =BS!E28 -> 73560.86 | F41: =BS!F28 -> 77006.98 | G41: =BS!G28 -> 77372.71 | H41: =G41+Assumptions!H27-H13 -> 77468.311 | I41: =H41+Assumptions!I27-I13 -> 77259.705 | J41: =I41+Assumptions!J27-J13 -> 76860.278 | K41: =J41+Assumptions!K27-K13 -> 76478.426 | L41: =K41+Assumptions!L27-L13 -> 76113.375
...

Sheet Valuation
A1: DCF Valuation (FCFF) - valuation date 31-Mar-2019
A2: Rs. crore unless stated | FCFF taken from the Model sheet | illustrative - not investment advice
A3: COST OF CAPITAL
A4: Risk-free rate | C4: 0.07 | D4: Indian 10-year G-Sec yield (assumption)
A5: Equity beta | C5: 1.2 | D5: Assumption for a cyclical steel producer
A6: Equity risk premium | C6: 0.065 | D6: Assumption
A7: Cost of equity (CAPM) = Rf + beta x ERP | C7: =C4+C5*C6 -> 0.148
A8: Pre-tax cost of debt | C8: 0.075 | D8: Assumption (= forecast interest rate)
A9: Tax rate | C9: =Assumptions!H15 -> 0.2517
A10: Post-tax cost of debt | C10: =C8*(1-C9) -> 0.0561225
A11: Target debt / (debt + equity) | C11: 0.35 | D11: Assumption
A12: WACC | C12: =C7*(1-C11)+C10*C11 -> 0.11584287
A13: Terminal growth rate | C13: 0.04 | D13: Assumption
A15: FREE CASH FLOW TO FIRM
A16: Particulars | H16: FY20E | I16: FY21E | J16: FY22E | K16: FY23E | L16: FY24E
A17: EBIT | H17: =Model!H14 -> 5736.6386 | I17: =Model!I14 -> 6522.7803 | J17: =Model!J14 -> 7388.1648 | K17: =Model!K14 -> 8223.6645 | L17: =Model!L14 -> 9117.7065
A18: Less: tax on EBIT | H18: =-MAX(H17,0)*Assumptions!H15 -> -1443.9119 | I18: =-MAX(I17,0)*Assumptions!I15 -> -1641.7838 | J18: =-MAX(J17,0)*Assumptions!J15 -> -1859.6011 | K18: =-MAX(K17,0)*Assumptions!K15 -> -2069.8964 | L18: =-MAX(L17,0)*Assumptions!L15 -> -2294.9267
A19: NOPAT | H19: =H17+H18 -> 4292.7266 | I19: =I17+I18 -> 4880.9965 | J19: =J17+J18 -> 5528.5637 | K19: =K17+K18 -> 6153.7681 | L19: =L17+L18 -> 6822.7798
A20: Add: depreciation and amortisation | H20: =Model!H13 -> 3404.3992 | I20: =Model!I13 -> 3408.6057 | J20: =Model!J13 -> 3399.427 | K20: =Model!K13 -> 3381.8522 | L20: =Model!L13 -> 3365.0507
A21: Change in working capital and other items | H21: =Model!H58 -> 236.80902 | I21: =Model!I58 -> -215.76317 | J21: =Model!J58 -> -230.86659 | K21: =Model!K58 -> -211.73764 | L21: =Model!L58 -> -224.4419
A22: Less: capital expenditure | H22: =Model!H60 -> -3500 | I22: =Model!I60 -> -3200 | J22: =Model!J60 -> -3000 | K22: =Model!K60 -> -3000 | L22: =Model!L60 -> -3000
A23: Free cash flow to firm (FCFF) | H23: =H19+H20+H21+H22 -> 4433.9349 | I23: =I19+I20+I21+I22 -> 4873.839 | J23: =J19+J20+J21+J22 -> 5697.1242 | K23: =K19+K20+K21+K22 -> 6323.8827 | L23: =L19+L20+L21+L22 -> 6963.3886
A24: Discount period (years, end-of-year) | H24: =COLUMN()-COLUMN($G$24) -> 1 | I24: =COLUMN()-COLUMN($G$24) -> 2 | J24: =COLUMN()-COLUMN($G$24) -> 3 | K24: =COLUMN()-COLUMN($G$24) -> 4 | L24: =COLUMN()-COLUMN($G$24) -> 5
A25: Discount factor | H25: =1/(1+$C$12)^H24 -> 0.89618352 | I25: =1/(1+$C$12)^I24 -> 0.80314491 | J25: =1/(1+$C$12)^J24 -> 0.71976523 | K25: =1/(1+$C$12)^K24 -> 0.64504174 | L25: =1/(1+$C$12)^L24 -> 0.57807578
A26: Present value of FCFF | H26: =H23*H25 -> 3973.6194 | I26: =I23*I25 -> 3914.399 | J26: =J23*J25 -> 4100.5919 | K26: =K23*K25 -> 4079.1684 | L26: =L23*L25 -> 4025.3663
A28: ENTERPRISE VALUE TO EQUITY VALUE
A29: Sum of PV of FCFF (FY20E-FY24E) | C29: =SUM(H26:L26) -> 20093.145
A30: Terminal-year FCFF = FY24E FCFF x (1+g) | C30: =L23*(1+C13) -> 7241.9242
A31: Terminal value (Gordon growth) = FCFF / (WACC - g) | C31: =C30/(C12-C13) -> 95485.887
A32: PV of terminal value | C32: =C31*L25 -> 55198.079
A33: Enterprise value | C33: =C29+C32 -> 75291.224
A34: Less: total borrowings (31-Mar-2019) | C34: =-(Model!G32+Model!G36) -> -41433.88
A35: Add: cash and cash equivalents | C35: =Model!G48 -> 219.42
A36: Add: non-current investments (non-operating, at book value) | C36: =Model!G42 -> 1584.75
A37: Equity value | C37: =SUM(C33:C36) -> 35661.514
A38: Number of shares (crore) | C38: =Model!G29/Assumptions!C6 -> 413.053
A39: Intrinsic value per share (Rs.) | C39: =C37/C38 -> 86.336412
A40: Terminal value as % of enterprise value | C40: =C32/C33 -> 0.73312766
A42: SENSITIVITY - intrinsic value per share (Rs.): WACC (down) vs terminal growth (across)
B43: WACC \ g | C43: =$C$13+(-0.01) -> 0.03 | D43: =$C$13+(-0.005) -> 0.035 | E43: =$C$13+(0) -> 0.04 | F43: =$C$13+(0.005) -> 0.045 | G43: =$C$13+(0.01) -> 0.05
...
