Workbook

Sheet Cover
A1: VOLTAS LIMITED
A2: Integrated Financial Model, DCF, Multiples & SoTP Valuation
A4: MODEL INFORMATION
A5: Company Name | B5: Voltas Limited
A6: NSE Ticker | B6: VOLTAS
A7: BSE Code | B7: 500575
A8: Industry | B8: Consumer Durables - Air Conditioning, Cooling & Engineering Projects
A9: Sector | B9: Tata Group
A10: Date of Valuation | B10: 19-Oct-2026
A11: Currency | B11: INR (Rs Crore, unless stated)
A12: FY Ending | B12: 31-March
A13: Model Type | B13: Three-Statement Model + DCF + Relative Valuation + SoTP
A14: Scenario (Live) | B14: Base case
A16: SEGMENT OVERVIEW (Voltas Ltd. Reporting Segments)
A17: 1. Unitary Cooling Products (Room Air Conditioners & Coolers) - RAC
A18: 2. Electro-Mechanical Projects & Services (EMPS) - Institutional & Government Projects
A19: 3. Engineering Products & Services (Mining & Construction Equipment, Water Management, Textile Machinery)
A20: 4. International Operations (Middle East, Africa, Southeast Asia - Electro-Mechanical Projects)
A22: WORKBOOK STATUS
A23: This workbook rebuilds the 21-page Voltas model report in Excel with live formulas (inputs in blue, formulas in black, cross-sheet links in green).
A24: Sheet "Checks" holds integrity checks and a tie-out of rebuilt outputs to the published report; sheet "Error_Log" lists the errors found in the published model and their valuation impact.
A25: Published figures are replicated first (including the errors); corrected values are shown alongside on DCF, Relative_Valuation and SoTP.
A26: Small (+/-1-4 Rs Cr) differences vs the report arise because the report displays rounded historical inputs; these are within the tolerances on the Checks sheet.

Sheet TOC
A1: TABLE OF CONTENTS
A3: # | B3: Worksheet | C3: Description
A4: 1 | B4: Cover | C4: Company & model information
A5: 2 | B5: TOC | C5: This page
A6: 3 | B6: Instructions | C6: Formatting conventions & how to use this model
A7: 4 | B7: Checks | C7: Integrity checks and tie-out to the published report (added)
A8: 5 | B8: Error_Log | C8: Errors found in the published model and valuation impact (added)
A9: 6 | B9: Hist_IS | C9: Historical Income Statement (FY23A-FY26A) & common-size
A10: 7 | B10: Hist_BS | C10: Historical Balance Sheet (FY23A-FY26A)
A11: 8 | B11: Hist_CF | C11: Historical Cash Flow Statement (FY23A-FY26A)
A12: 9 | B12: Assumptions | C12: Master assumptions - macro, segment drivers, margins
A13: 10 | B13: Revenue_Build | C13: Segment-wise revenue build-up (Volume x ASP)
A14: 11 | B14: Cost_Schedule | C14: Operating cost driver schedule
A15: 12 | B15: WC_Schedule | C15: Working capital schedule (days-based)
... A28: 25 | B28: SoTP | C28: Sum-of-the-Parts valuation with scenarios & sensitivities

Sheet Instructions
A1: INSTRUCTIONS - FORMATTING CONVENTIONS & HOW TO USE THIS MODEL
A3: Item | B3: Description
A4: Blue font | B4: Hard-coded input taken from the published report (historical data, assumptions, peer data).
A5: Blue font on peach fill | B5: Forecast / valuation assumption that can be changed (yellow-peach cells). Changing these flows through all sheets.
A6: Black font | B6: Formula on the same sheet.
A7: Green font | B7: Formula linking to another sheet.
A8: Units | B8: INR Crore unless stated; shares in crore; per-share values in Rs.
A9: Timeline | B9: Columns C-F = Mar-23A to Mar-26A (historical); columns G-K = Mar-27E to Mar-31E (forecast) on every time-series sheet.
A10: Flow of the model | B10: Assumptions -> Revenue_Build -> Cost_Schedule -> WC_Schedule / Capex_Dep / Debt_Schedule / Equity_Schedule -> Income_Statement -> Balance_Sheet -> Cash_Flow -> DCF.
A11: Valuation | B11: WACC (peer betas regressed in Market_Data) -> DCF; Relative_Valuation (peer trading multiples); Peer_Multiples -> SoTP.
A12: Published vs corrected | B12: Where the published model contains an error, the published logic is reproduced and a corrected figure is shown next to it (DCF section B, Relative_Valuation rows 29-41, SoTP column C). See Error_Log.
A13: Checks | B13: Review the Checks sheet after changing any input. "OK" = within tolerance; "REVIEW" = a known issue in the published model or source data (explained on the sheet).
A14: Scenario | B14: The "Scenario (Live)" label on the Cover is informational; scenarios are on the SoTP sheet (Low / Base / High).

Sheet Checks
A1: MODEL CHECKS & TIE-OUT TO THE PUBLISHED REPORT
A2: Status: OK = within tolerance. REVIEW = difference exceeds tolerance; for items marked "published issue" this is a genuine error/inconsistency in the published model (see Error_Log).
A4: A. INTEGRITY CHECKS
A5: # | B5: Check | C5: Value | D5: Tolerance | E5: Status | F5: Error_Log ref | G5: Comment
A6: 1 | B6: Revenue build total = historical income statement revenue (FY23-26, sum of abs differences) | C6: =SUMPRODUCT(ABS(Revenue_Build!C24:F24-Hist_IS!C12:F12)) -> 0 | D6: 0.01 | E6: =IF(ABS(C6)<=D6,"OK","REVIEW") -> OK | G6: Linked - must be zero
A7: 2 | B7: Historical balance sheets balance (FY23-26, sum of abs differences) | C7: =SUMPRODUCT(ABS(Hist_BS!C44:F44)) -> 1 | D7: 4 | E7: =IF(ABS(C7)<=D7,"OK","REVIEW") -> OK | F7: E-22 | G7: Source data rounding: +/-1 Cr in FY24 (report shows 14,510 vs 14,509 in FY26)
A8: 3 | B8: Forecast balance sheet balances (FY27-31, sum of abs differences) | C8: =SUMPRODUCT(ABS(Balance_Sheet!G43:K43)) -> 0 | D8: 0.5 | E8: =IF(ABS(C8)<=D8,"OK","REVIEW") -> OK | G8: Integrated model balances
A9: 4 | B9: Forecast cash flow closing cash = balance sheet cash (FY27-31) | C9: =SUMPRODUCT(ABS(Cash_Flow!G53:K53)) -> 0 | D9: 0.5 | E9: =IF(ABS(C9)<=D9,"OK","REVIEW") -> OK
A10: 5 | B10: Historical cash flow closing cash = historical balance sheet cash (FY23-26, sum of abs differences) | C10: =SUMPRODUCT(ABS(Hist_CF!C38:F38)) -> 121 | D10: 5 | E10: =IF(ABS(C10)<=D10,"OK","REVIEW") -> REVIEW | F10: E-04 | G10: Published issue: CF closing cash 693/814/650/741 vs BS 708/852/678/781
A11: 6 | B11: Historical cash flow opening cash = prior-year closing cash (FY24-26) | C11: =SUMPRODUCT(ABS(Hist_CF!D39:F39)) -> 2 | D11: 2 | E11: =IF(ABS(C11)<=D11,"OK","REVIEW") -> OK | F11: E-04 | G11: Rounding only
A12: 7 | B12: Cost_Schedule EBITDA = Income_Statement EBITDA (FY27-31) | C12: =SUMPRODUCT(ABS(Cost_Schedule!G18:K18-Income_Statement!G14:K14)) -> 0 | D12: 0.01 | E12: =IF(ABS(C12)<=D12,"OK","REVIEW") -> OK
A13: 8 | B13: PPE gross block roll-forward reconciles (FY23-26, sum of abs differences) | C13: =SUMPRODUCT(ABS(Capex_Dep!C13:F13)) -> 2 | D13: 3 | E13: =IF(ABS(C13)<=D13,"OK","REVIEW") -> OK | F13: E-08 | G13: Rounding in source data
A14: 9 | B14: EMPS order-book roll-forward FY26: opening + new orders - revenue - closing | C14: =Revenue_Build!F17 -> 447 | D14: 1 | E14: =IF(ABS(C14)<=D14,"OK","REVIEW") -> REVIEW | F14: E-07 | G14: Published issue: 447 Cr gap (closing OB 6,200 vs roll-forward 6,647)
A15: 10 | B15: EMPS FY26 execution rate: recomputed less hard-coded 39.5% | C15: =Revenue_Build!F16-Revenue_Build!F13 -> -0.016214953 | D15: 0.001 | E15: =IF(ABS(C15)<=D15,"OK","REVIEW") -> REVIEW | F15: E-07 | G15: Published issue: recomputed 37.9%
A16: 11 | B16: Other current assets days: used in WC_Schedule vs displayed on Assumptions page (sum abs diff, days) | C16: =SUMPRODUCT(ABS(Assumptions!G30:K30-Assumptions!G31:K31)) -> 187 | D16: 0.01 | E16: =IF(ABS(C16)<=D16,"OK","REVIEW") -> REVIEW | F16: E-05 | G16: Published issue: 25 days displayed, 60-67 days used
A17: 12 | B17: Peer market cap = CMP x shares (max relative difference) | C17: =SUMPRODUCT(ABS(Market_Data!O4:O8)/Market_Data!F4:F8) -> 4.9634827e-05 | D17: 0.001 | E17: =IF(ABS(C17)<=D17,"OK","REVIEW") -> OK | G17: Rounded share counts
A18: 13 | B18: Two WACCs: explicit-period WACC less terminal-value WACC | C18: =WACC!B44-WACC!B54 -> 0.0078286879 | D18: 0.0005 | E18: =IF(ABS(C18)<=D18,"OK","REVIEW") -> REVIEW | F18: E-03 | G18: Published issue: 13.6-13.7% vs 12.9%
A19: 14 | B19: Published FCFF overstated vs corrected FCFF (sum FY27-31) | C19: =SUM(Cash_Flow!G50:K50) -> 128.74421 | D19: 1 | E19: =IF(ABS(C19)<=D19,"OK","REVIEW") -> REVIEW | F19: E-01 | G19: Published issue: capex sign error
A20: 15 | B20: DCF section B (as published column) = DCF main value per share | C20: =DCF!B46-DCF!B30 -> 0 | D20: 0.001 | E20: =IF(ABS(C20)<=D20,"OK","REVIEW") -> OK
A21: 16 | B21: DCF sensitivity centre = DCF corrected value per share | C21: =DCF!B62 -> 0 | D21: 0.001 | E21: =IF(ABS(C21)<=D21,"OK","REVIEW") -> OK
A22: 17 | B22: Relative valuation weights total 100% | C22: =Relative_Valuation!L27 -> 0 | D22: 0.0001 | E22: =IF(ABS(C22)<=D22,"OK","REVIEW") -> OK
A23: 18 | B23: Relative valuation target price: as published less ex-Voltas | C23: =Relative_Valuation!L26-Relative_Valuation!L41 -> 36.695636 | D23: 0.5 | E23: =IF(ABS(C23)<=D23,"OK","REVIEW") -> REVIEW | F23: E-06 | G23: Published issue: peer stats include Voltas
A24: 19 | B24: SoTP base scenario = main result (value per share) | C24: =SoTP!C49 -> 0 | D24: 0.001 | E24: =IF(ABS(C24)<=D24,"OK","REVIEW") -> OK
A25: 20 | B25: SoTP sensitivity centre = base value per share | C25: =SoTP!C58 -> 0 | D25: 0.001 | E25: =IF(ABS(C25)<=D25,"OK","REVIEW") -> OK
A26: 21 | B26: SoTP segment EBIT vs model FY29E EBIT (relative difference) | C26: =SoTP!F17 -> 0.12312482 | D26: 0.02 | E26: =IF(ABS(C26)<=D26,"OK","REVIEW") -> REVIEW | F26: E-18 | G26: Published issue: segment EBIT 12% above model EBIT
A27: 22 | B27: SoTP discount factor: published less corrected | C27: =SoTP!B22-SoTP!C22 -> 0.21776351 | D27: 0.001 | E27: =IF(ABS(C27)<=D27,"OK","REVIEW") -> REVIEW | F27: E-20 | G27: Published issue: 1.000 although 1.9 years
A28: 23 | B28: Total debt: published (excl. current leases) less incl. current leases | C28: =Debt_Schedule!F23-Debt_Schedule!F25 -> -11 | D28: 0.5 | E28: =IF(ABS(C28)<=D28,"OK","REVIEW") -> REVIEW | F28: E-09 | G28: Published issue: current lease liabilities omitted
A29: 24 | B29: Net debt definitions: max less min across Ratios / DCF / Relative / SoTP | C29: =MAX(DCF!B27,Relative_Valuation!E6,SoTP!B25-SoTP!B24,Debt_Schedule!F26-Balance_Sheet!F39)-MIN(DCF!B27,Relative_Valuation!E6,SoTP!B25-SoTP!B24,Debt_Schedule!F26-Balance_Sheet!F39) -> 26 | D29: 2 | E29: =IF(ABS(C29)<=D29,"OK","REVIEW") -> REVIEW | F29: E-10 | G29: Published issue: 186 vs 201 vs 212 vs 211
B30: Checks passed / total | C30: =COUNTIF(E6:E29,"OK") -> 13 | D30: =COUNTA(E6:E29) -> 24
A32: B. TIE-OUT OF REBUILT MODEL TO THE PUBLISHED REPORT (published values keyed in from the PDF)
A33: # | B33: Item | C33: Published | D33: Rebuilt model | E33: Difference | F33: Tolerance | G33: Status
A34: 1 | B34: Revenue FY27E | C34: 16558 | D34: =Income_Statement!G6 -> 16557.061 | E34: =D34-C34 -> -0.9394 | F34: 2 | G34: =IF(ABS(E34)<=F34,"OK","REVIEW") -> OK
A35: 2 | B35: Revenue FY28E | C35: 19014 | D35: =Income_Statement!H6 -> 19013.776 | E35: =D35-C35 -> -0.2239786 | F35: 2 | G35: =IF(ABS(E35)<=F35,"OK","REVIEW") -> OK
A36: 3 | B36: Revenue FY29E | C36: 21432 | D36: =Income_Statement!I6 -> 21431.928 | E36: =D36-C36 -> -0.072344293 | F36: 2 | G36: =IF(ABS(E36)<=F36,"OK","REVIEW") -> OK
A37: 4 | B37: Revenue FY30E | C37: 23800 | D37: =Income_Statement!J6 -> 23799.898 | E37: =D37-C37 -> -0.10162553 | F37: 2 | G37: =IF(ABS(E37)<=F37,"OK","REVIEW") -> OK
A38: 5 | B38: Revenue FY31E | C38: 26484 | D38: =Income_Statement!K6 -> 26484.178 | E38: =D38-C38 -> 0.17811556 | F38: 2 | G38: =IF(ABS(E38)<=F38,"OK","REVIEW") -> OK
A39: 6 | B39: EBITDA FY27E | C39: 1043 | D39: =Income_Statement!G14 -> 1043.0948 | E39: =D39-C39 -> 0.0948178 | F39: 2 | G39: =IF(ABS(E39)<=F39,"OK","REVIEW") -> OK
A40: 7 | B40: EBITDA FY28E | C40: 1312 | D40: =Income_Statement!H14 -> 1311.9505 | E40: =D40-C40 -> -0.049454524 | F40: 2 | G40: =IF(ABS(E40)<=F40,"OK","REVIEW") -> OK
A41: 8 | B41: EBITDA FY29E | C41: 1543 | D41: =Income_Statement!I14 -> 1543.0988 | E41: =D41-C41 -> 0.098791211 | F41: 2 | G41: =IF(ABS(E41)<=F41,"OK","REVIEW") -> OK
A42: 9 | B42: EBITDA FY30E | C42: 1714 | D42: =Income_Statement!J14 -> 1713.5927 | E42: =D42-C42 -> -0.40731704 | F42: 2 | G42: =IF(ABS(E42)<=F42,"OK","REVIEW") -> OK
...

Sheet Error_Log
A1: ERROR & INCONSISTENCY LOG - PUBLISHED VOLTAS MODEL (21-page report)
A2: Each item was found by rebuilding the model and cross-checking every page. Impact figures are live formulas where a numeric impact can be computed.
A4: VALUATION SUMMARY: AS PUBLISHED vs CORRECTED (Rs per share)
A5: Method | C5: As published (rebuilt) | D5: Corrected | E5: Change | F5: Corrections applied
A6: DCF (FCFF) | C6: =DCF!B30 -> 370.22886 | D6: =DCF!D46 -> 317.74893 | E6: =D6-C6 -> -52.47993 | F6: E-01 capex sign; E-03 single WACC
A7: Relative valuation (peer multiples) | C7: =Relative_Valuation!L26 -> 686.0162 | D7: =Relative_Valuation!L41 -> 649.32057 | E7: =D7-C7 -> -36.695636 | F7: E-06 exclude Voltas from peer statistics
A8: Sum-of-the-parts (base) | C8: =SoTP!B29 -> 1234.6871 | D8: =SoTP!C29 -> 965.28412 | E8: =D8-C8 -> -269.40302 | F8: E-20 discount operating value 1.9 yrs at cost of equity
A9: SoTP low | C9: =SoTP!B46 -> 848.57102 | D9: =SoTP!B48 -> 663.25 | E9: =D9-C9 -> -185.32102 | F9: as above
A10: SoTP high | C10: =SoTP!D46 -> 1456.5457 | D10: =SoTP!D48 -> 1138.8299 | E10: =D10-C10 -> -317.71571 | F10: as above
A11: Current market price (Rs) | C11: =Assumptions!$C$8 -> 1033
A12: Note: the report itself gives no blended target; DCF, multiples and SoTP differ widely (367 / 686 / 1,235) even before corrections - the DCF is heavily driven by terminal value (86% of EV) and working-capital build.
A14: DETAILED FINDINGS
A15: ID | B15: Sheet / location | C15: Severity | D15: Finding | E15: Evidence | F15: Impact (live) | G15: Impact unit / meaning | H15: Recommended fix | I15: Treatment in this workbook
A16: E-01 | B16: Cash_Flow - FCFF block (published p.14) -> DCF | C16: High | D16: FCFF deducts capex as (PPE capex - ROU additions) instead of (PPE capex + ROU additions). The cash-flow statement itself uses 225/259/356/324/360. | E16: Published capex 205/236/330/295/328 vs correct 225/259/356/324/360; FCFF overstated by 20/23/26/29/32 (130 over five years). | F16: =DCF!C49 -> -13.418157 | G16: Rs per share change in DCF value from fixing capex only | H16: Use Capex + ROU additions (= CFI capex) in the FCFF block. | I16: Replicated as published (row "as published"); corrected FCFF on Cash_Flow and DCF col C.
A17: E-02 | B17: DCF (published p.18) header | C17: Low | D17: Column headers read FY26E-FY30E but the cash flows are FY27E-FY31E (the PV line below even says FY27E-FY31E). | E17: Header FY26E..FY30E vs FCFF 400/240/676/291/963 = FY27E..FY31E. | H17: Relabel headers FY27E-FY31E. | I17: Headers corrected.
A18: E-03 | B18: WACC (p.17) / DCF (p.18) | C18: High | D18: Two different WACCs are used: 13.7% (beta 1.14) for the explicit period and a separate 12.9% (beta hard-coded 1.00) for the terminal value, which widens the TV and is not explained. | E18: Explicit discount factors imply 13.66%; TV = 1,034/(12.9% - 7.4%) = 18,809. | F18: =DCF!D46-DCF!C46 -> -39.061773 | G18: Rs per share change from using one WACC (after fixing E-01) | H18: Use a single WACC (or justify a lower terminal WACC) and link both to the same beta. | I18: Both reproduced; DCF section B shows effect.
A19: E-04 | B19: Hist_CF (p.5) vs Hist_BS (p.4) | C19: Medium | D19: Historical closing cash in the cash flow statement does not agree with balance sheet cash; FY26 opening cash (650) also differs from FY25 closing (649). | E19: CF closing 693/816/649/740 vs BS 708/852/678/781. | F19: =Hist_CF!F38 -> -40 | G19: FY26 difference, Rs Cr (CF less BS) | H19: Reconcile (bank overdrafts / other bank balances) or restate cash definition; forecast starts from BS cash 781. | I19: Reproduced; difference shown on Hist_CF and Checks.
A20: E-05 | B20: Assumptions (p.6) vs WC_Schedule (p.9) | C20: Medium | D20: Assumptions page shows Other Current Assets Days = 25.0 for every forecast year, but the working-capital schedule uses 67/63/61/61/60 days ("Forecast = Assumptions link" is broken). | E20: OCA FY27 3,039 = 16,558 x 67/365; at 25 days it would be 1,134. | F20: =WC_Schedule!G17-WC_Schedule!G6*Assumptions!G31/365 -> 1905.196 | G20: FY27 OCA balance higher than a 25-day assumption, Rs Cr (cash tied up) | H20: Link WC_Schedule to the assumption cell or correct the assumption page; decide which days are intended. | I20: Inputs set to the days actually used; displayed 25 kept as a memo row.
A21: E-06 | B21: Relative_Valuation (p.19) | C21: High | D21: Peer statistics (median/average/quartiles) include Voltas itself, so the EV/Revenue implied value equals the current price (circular) and medians are biased toward Voltas. | E21: Implied EV/Revenue value Rs 1,033.16 vs CMP 1,032.85. Ex-Voltas medians: EV/Rev 2.4x, EV/EBITDA 32.4x, P/E 65.3x. | F21: =Relative_Valuation!L41-Relative_Valuation!L26 -> -36.695636 | G21: Rs change in blended target price when Voltas is excluded | H21: Exclude the target company from peer statistics. | I21: Published calc reproduced; corrected block on Relative_Valuation rows 29-41.
A22: E-07 | B22: Revenue_Build (p.7) | C22: Medium | D22: EMPS FY26: execution rate hard-coded at 39.5% but actual revenue / (opening OB + new orders) is 37.9%; order book does not roll forward (6,500 + 4,200 - 4,053 = 6,647, not 6,200). Forecast opening OB of 6,200 may understate EMPS revenue. | E22: FY26 roll-forward gap 447 Cr; at 39% execution a 447 Cr higher opening OB adds ~174 Cr FY27 EMPS revenue. | F22: =Revenue_Build!F17 -> 447 | G22: Rs Cr gap in FY26 closing order book | H22: Confirm FY26 closing order book from reported data and make opening OB / execution rate consistent. | I22: Reproduced; check rows added on Revenue_Build.
A23: E-08 | B23: Capex_Dep (p.10) | C23: Low | D23: Two rows are both labelled "Less: Disposal"; the second one is added back in the roll-forward (it is an adjustment/transfer, not a disposal). | E23: Gross block FY26: 1,161 + 183 - 17 + 11 = 1,338; accumulated depn 341 + 70 - 15 + 7 = 403. | H23: Relabel second row "Add: other adjustments / transfers". | I23: Relabelled.
A24: E-09 | B24: Debt_Schedule (p.11) | C24: Low | D24: "Lease Liabilities (Total)" contains only non-current leases (15); current leases (11) are left out of Total Debt. The ST borrowings row labelled "% (Receivables + Inventories)" actually shows the rupee increase. FY26A total debt shows 981 vs 982 sum of components. | E24: Total debt incl. current leases FY26 = 993 vs 981-982 shown. | F24: =Debt_Schedule!F24 -> 11 | G24: Rs Cr debt omitted from published Total Debt | H24: Include current lease liabilities and fix labels. | I24: Memo row added (total incl. current leases).
A25: E-10 | B25: Ratios / DCF / Relative_Valuation / SoTP | C25: Medium | D25: Net debt is defined four different ways: Ratios 186 (LT+ST borrowings less cash), DCF 200, Relative 212 (Screener), SoTP 211 (992 less 781). Debt of 992 vs 982/967 also differs. | E25: 186 vs 200/201 vs 212 vs 211. | F25: =MAX(DCF!B27,Relative_Valuation!E6,SoTP!B25-SoTP!B24,Debt_Schedule!F26-Balance_Sheet!F39)-MIN(DCF!B27,Relative_Valuation!E6,SoTP!B25-SoTP!B24,Debt_Schedule!F26-Balance_Sheet!F39) -> 26 | G25: Rs Cr spread between highest and lowest net debt | H25: Adopt one definition (e.g. borrowings + leases - cash and liquid investments) across all valuation sheets. | I25: Each method kept as published.
A26: E-11 | B26: Cost_Schedule (p.8) | C26: Low | D26: The forecast line labelled "Sub-Contracting / Erection Charges (EMPS)" actually holds total Other Expenses (selling, admin, freight, power etc.); Hist_IS shows sub-contracting as blank. | E26: FY26: 1,589 = Other expenses on Hist_IS. | H26: Relabel as Other Expenses. | I26: Label clarified.
A27: E-12 | B27: Assumptions (p.6) - interest rates | C27: Low | D27: Average interest rates on LT (7.0%-6.7%) and ST debt (7.9%-7.5%) are inputs but are not used; finance cost is driven by "% of revenue". Implied interest on the debt schedule differs from the finance cost in the income statement. | E27: FY27 finance cost 101 vs rate-based estimate on average debt. | F27: =Income_Statement!G19-(AVERAGE(Debt_Schedule!F10,Debt_Schedule!G10)*Assumptions!G36+AVERAGE(Debt_Schedule!F15,Debt_Schedule!G15)*Assumptions!G37) -> 27.731305 | G27: FY27 Rs Cr: model finance cost less rate-based interest | H27: Drive finance cost off debt balances x rates (and leases) or remove unused inputs. | I27: Reproduced; inputs flagged "not used".
A28: E-13 | B28: Income_Statement / Cash_Flow (pp.12,14) | C28: Low | D28: Share of JV loss (-131 each year) is a non-cash charge but is not added back in CFO and NC investments stay flat, i.e. the model implicitly funds JV losses in cash inside operating cash flow. FCFF (EBIT-based) ignores this funding. | E28: JV loss -131 p.a. reduces cash by 655 over FY27-31. | F28: =-Income_Statement!G21 -> 131 | G28: Rs Cr per year of JV loss treated as cash | H28: Show JV funding in investing cash flow (or add back loss and reduce investment) and reflect it in valuation. | I28: Reproduced (no effect on balancing).
A29: E-14 | B29: DCF (p.18) - terminal growth | C29: Medium | D29: Terminal growth (7.4%) is linked to the risk-free rate; combined with the low terminal WACC the spread is only ~5.5% and terminal value is 86% of EV. Valuation is extremely sensitive to this. | E29: TV % of EV = 85.6%; each +1pt of g adds roughly Rs 40-55 per share at the corrected WACC (see DCF sensitivity). | F29: =DCF!B48 -> 0.85600968 | G29: Terminal value as % of EV | H29: Justify g separately from Rf (usually 4-6% for long-run nominal growth) and show sensitivity. | I29: Reproduced; sensitivity grid added on DCF.
A30: E-15 | B30: DCF (p.18) - equity bridge | C30: Medium | D30: Equity value deducts only net debt; non-current investments (2,307) and current investments (277) are ignored, while the JV funding burn is also excluded from FCFF. SoTP, by contrast, adds the JV at book value. | E30: Excluded investments 2,584 Cr = Rs 78 per share. | F30: =DCF!B50/DCF!B29 -> 78.113664 | G30: Rs per share of excluded investments (book) | H30: Add value of non-operating investments (and JV) consistently across DCF and SoTP. | I30: Memo only (not applied).
A31: E-16 | B31: Market_Data vs Relative_Valuation (pp.16,19) | C31: Medium | D31: Peer data differ between the WACC/Market_Data page and the Relative_Valuation page: Amber price 6,688.55 vs 6,668.00; Voltas net income 442.2 vs 370.0; LG 1,824.7 vs 1,685.0; Crompton -228.1 vs 516.0; sales and market caps also differ. | E31: Voltas NP 442.2 (12M) vs 370.0 (FY26); Amber price difference shown at right. | F31: =Market_Data!C7-Relative_Valuation!B8 -> 20.55 | G31: Rs per share Amber price difference | H31: Use a single dated data set for all peer analysis. | I31: Both data sets reproduced.
A32: E-17 | B32: Assumptions vs SoTP | C32: Low | D32: Forecast effective tax rate is 30%, SoTP uses 25% and WACC sheet uses 25%. | E32: 30% vs 25% (PAT used in SoTP is ~7% higher than at 30%). | F32: =Assumptions!G25-SoTP!B6 -> 0.05 | G32: Percentage-point difference in tax rate | H32: Use one tax-rate assumption (or document the reason). | I32: Reproduced.
A33: E-18 | B33: SoTP (p.21) - tie-out | C33: High | D33: Segment EBIT in the SoTP (1,595) does not reconcile to the model FY29E EBIT (1,420); the "for tie-out check" input is shown but never used. Overall margin 7.4% vs model 6.6% (unallocated costs not charged). | E33: SoTP EBIT 1,595 vs model 1,420: +175 Cr (+12.3%). | F33: =SoTP!E17 -> 174.83809 | G33: Rs Cr SoTP segment EBIT above model EBIT | H33: Reconcile segment margins to consolidated EBIT or allocate corporate costs. | I33: Tie-out row added (SoTP row 17).
A34: E-19 | B34: SoTP (p.21) - borrowings note | C34: Low | D34: Note says borrowings = term loan 423 + working-capital debt 544 + leases ~15 = 982, but 992 is deducted. | E34: 423 + 544 + 15 = 982 vs 992 used. | F34: =SoTP!B25-(423+544+15) -> 10 | G34: Rs Cr over-deduction | H34: Correct the amount or the note. | I34: Published 992 retained.
A35: E-20 | B35: SoTP (p.21) - discount factor | C35: High | D35: "Years from today to valuation date" = 1.9 but the discount factor is 1.000, so FY29E-based operating value is not discounted to today (the multiples are applied to FY29E earnings at Sep-28). | E35: Discount factor 1.000 vs 1/(1+13.8%)^1.9 = 0.78. | F35: =SoTP!C29-SoTP!B29 -> -269.40302 | G35: Rs per share change when discounted | H35: Apply the discount factor (e.g. at cost of equity) or explain why none is needed. | I35: Published reproduced; corrected column C added.
A36: E-21 | B36: SoTP (p.21) | C36: Low | D36: Revenue-share total shows 99.6% (excludes "Other Unallocated" 0.4%). | E36: Total should be 100%. | H36: Include Other in the total. | I36: Corrected.
A37: E-22 | B37: Hist_IS / Hist_BS / Hist_CF (pp.3-5) | C37: Low | D37: Source data are rounded to whole crores so statements do not foot exactly (e.g. FY26 total E&L 14,510 vs total assets 14,509; FY23 PBT 307 vs derived 306; closing equity+liabilities FY24-25 off by 1). | E37: Check rows added. | F37: =SUMPRODUCT(ABS(Hist_BS!C44:F44)) -> 1 | G37: Rs Cr sum of absolute BS differences FY23-26 | H37: Load unrounded statements. | I37: Totals computed by formula; differences of +/-1 vs report.
A38: E-23 | B38: Hist_IS / Relative / Market_Data | C38: Low | D38: Share count is shown as 33.1 (EPS), 33.09 (market data) and 33.08 (SoTP, DCF and ratios). | E38: 33.1 / 33.09 / 33.08. | H38: Use one share count. | I38: 33.08 used throughout.
A39: E-24 | B39: DCF / Cover - timing | C39: Medium | D39: Valuation date is 19-Oct-2026 but cash flows are discounted from 1-Apr-2026 (FY27 at 0.5 years) and the equity bridge uses 31-Mar-2026 net debt; roughly half of FY27 has already elapsed. | E39: Date of valuation 19-Oct-2026 vs period start 1-Apr-2026. | H39: Roll the valuation date forward (stub period) or state the valuation date as 31-Mar-2026. | I39: Not changed (flagged).
A40: E-25 | B40: Equity_Schedule / Cash_Flow | C40: Low | D40: Dividends are held flat at 132 Cr (Rs 4/share) vs 232 Cr paid in FY26 despite profit tripling. | E40: FY26 dividend 232 vs forecast 132. | F40: =-Hist_CF!F27-Equity_Schedule!G12 -> 99.68 | G40: Rs Cr lower dividends than FY26 | H40: Link dividends to a payout ratio. | I40: Reproduced (DPS Rs 4 assumption).
A41: E-26 | B41: Ratios (p.15) | C41: Low | D41: ROE uses average equity (FY24 onwards) whereas ROA, ROCE, asset and inventory turnover use closing balances; Net Debt/EBITDA excludes leases while Debt/Equity includes non-current leases. | E41: Mixed conventions. | H41: Use consistent average-balance conventions. | I41: Reproduced; conventions stated in labels.
A42: E-27 | B42: WACC (p.17) | C42: Low | D42: Pre-tax cost of debt displays 7.9% while Rf 7.4% + spread 0.6% = 8.0% (after-tax 6.0% is consistent with 8.0%). Rebuilt WACC 13.64% vs 13.7% shown; TV WACC 12.86% vs 12.9%. | F42: =WACC!B44-0.137 -> -0.00057131214 | G42: Rebuilt less published explicit WACC | H42: Show unrounded inputs. | I42: Rebuilt from displayed inputs; small variance (see Checks).
...

Sheet Hist_IS
A1: VOLTAS LIMITED - HISTORICAL INCOME STATEMENT
A2: INR Crore unless stated
C4: HISTORICAL
A5: Particulars | B5: Unit | C5: Mar-23A | D5: Mar-24A | E5: Mar-25A | F5: Mar-26A
A6: SEGMENT REVENUE (Rs Cr)
A7: Unitary Cooling Products (RAC) | B7: Rs Cr | C7: 6475 | D7: 8160 | E7: 10614 | F7: 9501
A8: Electro-Mechanical Projects & Services (EMPS) | B8: Rs Cr | C8: 2403 | D8: 3683 | E8: 4157 | F8: 4053
A9: Engineering Products & Services | B9: Rs Cr | C9: 522 | D9: 588 | E9: 569 | F9: 599
A10: International Operations | B10: Rs Cr
A11: Others / Unallocated | B11: Rs Cr | C11: 99 | D11: 50 | E11: 73 | F11: 92
A12: Total Revenue from Operations | C12: =SUM(C7:C11) -> 9499 | D12: =SUM(D7:D11) -> 12481 | E12: =SUM(E7:E11) -> 15413 | F12: =SUM(F7:F11) -> 14245
A13: OPERATING EXPENSES (Rs Cr)
A14: Cost of Materials Consumed | B14: Rs Cr | C14: 4808 | D14: 6778 | E14: 8126 | F14: 8256
A15: Purchase of Stock-in-Trade | B15: Rs Cr | C15: 2296 | D15: 3427 | E15: 4017 | F15: 3083
A16: Changes in Inventories | B16: Rs Cr | C16: 274 | D16: -391 | E16: -183 | F16: -270
A17: Employee Benefit Expense | B17: Rs Cr | C17: 667 | D17: 779 | E17: 890 | F17: 939
A18: Sub-contracting / Erection Charges (EMPS) | B18: Rs Cr
A19: Other Expenses (Selling, Admin, Freight, Power) | B19: Rs Cr | C19: 881 | D19: 1414 | E19: 1446 | F19: 1589
A20: Total Expenses (before D&A and Finance Cost) | C20: =SUM(C14:C19) -> 8926 | D20: =SUM(D14:D19) -> 12007 | E20: =SUM(E14:E19) -> 14296 | F20: =SUM(F14:F19) -> 13597
A22: EBITDA | C22: =C12-C20 -> 573 | D22: =D12-D20 -> 474 | E22: =E12-E20 -> 1117 | F22: =F12-F20 -> 648
A23: EBITDA Margin % | C23: =C22/C12 -> 0.060322139 | D23: =D22/D12 -> 0.037977726 | E23: =E22/E12 -> 0.07247129 | F23: =F22/F12 -> 0.045489645
A24: Depreciation & Amortization | B24: Rs Cr | C24: 40 | D24: 48 | E24: 62 | F24: 84
A25: EBIT | C25: =C22-C24 -> 533 | D25: =D22-D24 -> 426 | E25: =E22-E24 -> 1055 | F25: =F22-F24 -> 564
A26: Finance Costs | B26: Rs Cr | C26: 30 | D26: 56 | E26: 62 | F26: 87
A27: Other Income | B27: Rs Cr | C27: 168 | D27: 253 | E27: 324 | F27: 238
A28: Share of Profit from Associates / JV | B28: Rs Cr | C28: -121 | D28: -139 | E28: -126 | F28: -131
A29: Exceptional Items | B29: Rs Cr | C29: -244 | D29: 0 | E29: 0 | F29: -26
A30: Profit Before Tax (PBT) | C30: =C25-C26+C27+C28+C29 -> 306 | D30: =D25-D26+D27+D28+D29 -> 484 | E30: =E25-E26+E27+E28+E29 -> 1191 | F30: =F25-F26+F27+F28+F29 -> 558
A31: Tax Expense (Current + Deferred) | B31: Rs Cr | C31: 171 | D31: 238 | E31: 356 | F31: 187
A32: Effective Tax Rate % | C32: =C31/C30 -> 0.55882353 | D32: =D31/D30 -> 0.49173554 | E32: =E31/E30 -> 0.29890848 | F32: =F31/F30 -> 0.33512545
A33: Profit After Tax (PAT) | C33: =C30-C31 -> 135 | D33: =D30-D31 -> 246 | E33: =E30-E31 -> 835 | F33: =F30-F31 -> 371
A34: Non-Controlling / Minority Interest | B34: Rs Cr
A35: Net Profit Attributable to Owners | C35: =C33-N(C34) -> 135 | D35: =D33-N(D34) -> 246 | E35: =E33-N(E34) -> 835 | F35: =F33-N(F34) -> 371
A37: Weighted Avg. Diluted Shares Outstanding (Cr) | B37: Cr Shares | C37: =Assumptions!$C$9 -> 33.08 | D37: =Assumptions!$C$9 -> 33.08 | E37: =Assumptions!$C$9 -> 33.08 | F37: =Assumptions!$C$9 -> 33.08
A38: Diluted EPS (Rs) | C38: =C35/C37 -> 4.0810157 | D38: =D35/D37 -> 7.4365175 | E38: =E35/E37 -> 25.241838 | F38: =F35/F37 -> 11.215236
A39: COMMON-SIZE ANALYSIS (% of Total Revenue)
A40: Cost of Materials Consumed % | C40: =C14/C12 -> 0.50615854 | D40: =D14/D12 -> 0.54306546 | E40: =E14/E12 -> 0.52721728 | F40: =F14/F12 -> 0.57957178
A41: Employee Cost % | C41: =C17/C12 -> 0.070217918 | D41: =D17/D12 -> 0.062414871 | E41: =E17/E12 -> 0.057743463 | F41: =F17/F12 -> 0.065917866
A42: Other Expenses % | C42: =C19/C12 -> 0.092746605 | D42: =D19/D12 -> 0.1132922 | E42: =E19/E12 -> 0.093816908 | F42: =F19/F12 -> 0.11154791
A43: EBITDA Margin % | C43: =C22/C12 -> 0.060322139 | D43: =D22/D12 -> 0.037977726 | E43: =E22/E12 -> 0.07247129 | F43: =F22/F12 -> 0.045489645
...

Sheet Hist_BS
A1: VOLTAS LIMITED - HISTORICAL BALANCE SHEET
A2: INR Crore unless stated
C4: HISTORICAL
A5: Particulars | B5: Unit | C5: Mar-23A | D5: Mar-24A | E5: Mar-25A | F5: Mar-26A
A6: EQUITY & LIABILITIES
A7: Share Capital | B7: Rs Cr | C7: 33 | D7: 33 | E7: 33 | F7: 33
A8: Other Equity (Reserves & Surplus) | B8: Rs Cr | C8: 5419 | D8: 5787 | E8: 6480 | F8: 6343
A9: Non-Controlling Interest | B9: Rs Cr | C9: 42 | D9: 34 | E9: 27 | F9: 23
A10: Total Equity | C10: =SUM(C7:C9) -> 5494 | D10: =SUM(D7:D9) -> 5854 | E10: =SUM(E7:E9) -> 6540 | F10: =SUM(F7:F9) -> 6399
A12: Long Term Borrowings | B12: Rs Cr | C12: 21 | D12: 228 | E12: 383 | F12: 376
A13: Lease Liabilities (Non-Current) | B13: Rs Cr | C13: 25 | D13: 21 | E13: 18 | F13: 15
A14: Deferred Tax Liabilities (Net) | B14: Rs Cr | C14: 5 | D14: 59 | E14: 58 | F14: 14
A15: Other Non-Current Liabilities & Provisions | B15: Rs Cr | C15: 114 | D15: 117 | E15: 147 | F15: 152
A16: Total Non-Current Liabilities | C16: =SUM(C12:C15) -> 165 | D16: =SUM(D12:D15) -> 425 | E16: =SUM(E12:E15) -> 606 | F16: =SUM(F12:F15) -> 557
A18: Short Term Borrowings | B18: Rs Cr | C18: 595 | D18: 485 | E18: 481 | F18: 591
A19: Lease Liabilities (Current) | B19: Rs Cr | C19: 9 | D19: 9 | E19: 11 | F19: 11
A20: Trade Payables | B20: Rs Cr | C20: 3013 | D20: 3856 | E20: 3893 | F20: 5228
A21: Other Current Liabilities & Provisions | B21: Rs Cr | C21: 1003 | D21: 1406 | E21: 1621 | F21: 1724
A22: Total Current Liabilities | C22: =SUM(C18:C21) -> 4620 | D22: =SUM(D18:D21) -> 5756 | E22: =SUM(E18:E21) -> 6006 | F22: =SUM(F18:F21) -> 7554
A23: TOTAL EQUITY & LIABILITIES | C23: =C10+C16+C22 -> 10279 | D23: =D10+D16+D22 -> 12035 | E23: =E10+E16+E22 -> 13152 | F23: =F10+F16+F22 -> 14510
A25: ASSETS
A26: Net Block - Property, Plant & Equipment | B26: Rs Cr | C26: 361 | D26: 390 | E26: 820 | F26: 935
A27: Capital Work in Progress | B27: Rs Cr | C27: 98 | D27: 368 | E27: 82 | F27: 22
A28: Right-of-Use Assets | B28: Rs Cr | C28: 36 | D28: 35 | E28: 34 | F28: 32
A29: Intangible Assets & Goodwill | B29: Rs Cr | C29: 79 | D29: 78 | E29: 76 | F29: 76
A30: Non-Current Investments | B30: Rs Cr | C30: 2531 | D30: 2768 | E30: 2638 | F30: 2307
A31: Deferred Tax Assets (Net) | B31: Rs Cr | C31: 36 | D31: 41 | E31: 44 | F31: 51
A32: Other Non-Current Assets | B32: Rs Cr | C32: 692 | D32: 632 | E32: 580 | F32: 758
A33: Total Non-Current Assets | C33: =SUM(C26:C32) -> 3833 | D33: =SUM(D26:D32) -> 4312 | E33: =SUM(E26:E32) -> 4274 | F33: =SUM(F26:F32) -> 4181
A35: Inventories | B35: Rs Cr | C35: 1592 | D35: 2135 | E35: 2715 | F35: 3433
A36: Trade Receivables | B36: Rs Cr | C36: 2192 | D36: 2533 | E36: 2511 | F36: 3035
A37: Cash & Cash Equivalents | B37: Rs Cr | C37: 708 | D37: 852 | E37: 678 | F37: 781
A38: Current Investments | B38: Rs Cr | C38: 307 | D38: 501 | E38: 399 | F38: 277
A39: Contract Assets | B39: Rs Cr | C39: 978 | D39: 744 | E39: 1300 | F39: 1867
A40: Other Current Assets (incl. Unbilled Revenue) | B40: Rs Cr | C40: 669 | D40: 959 | E40: 1275 | F40: 936
A41: Total Current Assets | C41: =SUM(C35:C40) -> 6446 | D41: =SUM(D35:D40) -> 7724 | E41: =SUM(E35:E40) -> 8878 | F41: =SUM(F35:F40) -> 10329
A42: TOTAL ASSETS | C42: =C33+C41 -> 10279 | D42: =D33+D41 -> 12036 | E42: =E33+E41 -> 13152 | F42: =F33+F41 -> 14510
A44: Check: Total Assets - Total Equity & Liabilities (rounding in source data) | C44: =C42-C23 -> 0 | D44: =D42-D23 -> 1 | E44: =E42-E23 -> 0 | F44: =F42-F23 -> 0

Sheet Hist_CF
A1: VOLTAS LIMITED - HISTORICAL CASH FLOW STATEMENT (Indirect Method)
A2: INR Crore unless stated
C4: HISTORICAL
A5: Particulars | B5: Unit | C5: Mar-23A | D5: Mar-24A | E5: Mar-25A | F5: Mar-26A
A6: CASH FLOW FROM OPERATING ACTIVITIES
A7: Profit Before Tax | C7: =Hist_IS!C30 -> 306 | D7: =Hist_IS!D30 -> 484 | E7: =Hist_IS!E30 -> 1191 | F7: =Hist_IS!F30 -> 558
A8: Add: Depreciation & Amortization | C8: =Hist_IS!C24 -> 40 | D8: =Hist_IS!D24 -> 48 | E8: =Hist_IS!E24 -> 62 | F8: =Hist_IS!F24 -> 84
A9: Add: Finance Costs | C9: =Hist_IS!C26 -> 30 | D9: =Hist_IS!D26 -> 56 | E9: =Hist_IS!E26 -> 62 | F9: =Hist_IS!F26 -> 87
A10: Other Non-Cash Adjustments | B10: Rs Cr | C10: 333 | D10: 304 | E10: -134 | F10: -95
A11: Changes in Working Capital | B11: Rs Cr | C11: -384 | D11: 80 | E11: -1094 | F11: -352
A12: Less: Direct Taxes Paid | B12: Rs Cr | C12: -166 | D12: -212 | E12: -311 | F12: -211
A13: Net Cash from Operating Activities (CFO) | C13: =SUM(C7:C12) -> 159 | D13: =SUM(D7:D12) -> 760 | E13: =SUM(E7:E12) -> -224 | F13: =SUM(F7:F12) -> 71
A15: CASH FLOW FROM INVESTING ACTIVITIES
A16: Purchase of PPE / Capex | B16: Rs Cr | C16: -180 | D16: -293 | E16: -208 | F16: -133
A17: Proceeds from Sale of Assets | B17: Rs Cr | C17: 2 | D17: 5 | E17: 17 | F17: 4
A18: Purchase/Sale of Investments (Net) | B18: Rs Cr | C18: 25 | D18: -318 | E18: 218 | F18: 306
A19: Interest & Dividend Received | B19: Rs Cr | C19: 71 | D19: 83 | E19: 131 | F19: 105
A20: Net Cash from Investing Activities (CFI) | C20: =SUM(C16:C19) -> -82 | D20: =SUM(D16:D19) -> -523 | E20: =SUM(E16:E19) -> 158 | F20: =SUM(F16:F19) -> 282
A22: CASH FLOW FROM FINANCING ACTIVITIES
A23: Proceeds from Borrowings | B23: Rs Cr | C23: 1504 | D23: 590 | E23: 454 | F23: 2112
A24: Repayment of Borrowings | B24: Rs Cr | C24: -1231 | D24: -493 | E24: -304 | F24: -2039
A25: Payment of Lease Liabilities | B25: Rs Cr | C25: -10 | D25: -18 | E25: -14 | F25: -14
A26: Interest Paid | B26: Rs Cr | C26: -25 | D26: -52 | E26: -54 | F26: -89
A27: Dividend Paid | B27: Rs Cr | C27: -183 | D27: -143 | E27: -182 | F27: -232
A28: Buyback of Shares / Other | B28: Rs Cr | C28: 0 | D28: 0 | E28: 0 | F28: 0
A29: Net Cash from Financing Activities (CFF) | C29: =SUM(C23:C28) -> 55 | D29: =SUM(D23:D28) -> -116 | E29: =SUM(E23:E28) -> -100 | F29: =SUM(F23:F28) -> -262
A31: Net Increase / (Decrease) in Cash | C31: =C13+C20+C29 -> 132 | D31: =D13+D20+D29 -> 121 | E31: =E13+E20+E29 -> -166 | F31: =F13+F20+F29 -> 91
A32: Opening Cash & Cash Equivalents | B32: Rs Cr | C32: 561 | D32: 693 | E32: 816 | F32: 650
A33: Closing Cash & Cash Equivalents | C33: =C32+C31 -> 693 | D33: =D32+D31 -> 814 | E33: =E32+E31 -> 650 | F33: =F32+F31 -> 741
A35: Free Cash Flow to Firm proxy (CFO - Capex) | C35: =C13+C16 -> -21 | D35: =D13+D16 -> 467 | E35: =E13+E16 -> -432 | F35: =F13+F16 -> -62
A36: RECONCILIATION CHECKS (added)
A37: Cash & cash equivalents per Balance Sheet | C37: =Hist_BS!C37 -> 708 | D37: =Hist_BS!D37 -> 852 | E37: =Hist_BS!E37 -> 678 | F37: =Hist_BS!F37 -> 781
A38: Difference: CF closing cash - Balance Sheet cash | C38: =C33-C37 -> -15 | D38: =D33-D37 -> -38 | E38: =E33-E37 -> -28 | F38: =F33-F37 -> -40
A39: Difference: CF opening cash - prior year CF closing cash | D39: =D32-C33 -> 0 | E39: =E32-D33 -> 2 | F39: =F32-E33 -> 0

Sheet Assumptions
A1: VOLTAS LIMITED - MASTER ASSUMPTIONS
A2: INR Crore unless stated
C4: HISTORICAL | G4: FORECAST
A5: Particulars | B5: Unit | C5: Mar-23A | D5: Mar-24A | E5: Mar-25A | F5: Mar-26A | G5: Mar-27E | H5: Mar-28E | I5: Mar-29E | J5: Mar-30E | K5: Mar-31E
A6: A. GENERAL
A7: Date of valuation | B7: text | C7: 19-Oct-2026
A8: Current market price used in valuation (Rs per share) | B8: Rs | C8: 1033
A9: Diluted shares outstanding (Cr) | B9: Cr | C9: 33.08
A10: B. SEGMENT 1 - UNITARY COOLING PRODUCTS (ROOM AC & COOLERS)
A11: RAC Industry Volume Growth % | B11: % | G11: 0.16 | H11: 0.11 | I11: 0.1 | J11: 0.09 | K11: 0.08
A12: Voltas Market Share % | B12: % | F12: 0.16 | G12: 0.16 | H12: 0.165 | I12: 0.168 | J12: 0.17 | K12: 0.174
A13: Implied Voltas Volume Growth % | B13: % | G13: =(1+G11)*G12/F12-1 -> 0.16 | H13: =(1+H11)*H12/G12-1 -> 0.1446875 | I13: =(1+I11)*I12/H12-1 -> 0.12 | J13: =(1+J11)*J12/I12-1 -> 0.10297619 | K13: =(1+K11)*K12/J12-1 -> 0.10541176
A14: Realization / ASP Growth % (Price Increase) | B14: % | G14: 0.06 | H14: 0.035 | I14: 0.03 | J14: 0.025 | K14: 0.025
A15: C. SEGMENT 2 - ELECTRO-MECHANICAL PROJECTS & SERVICES (EMPS)
A16: New Order Inflow Growth % | B16: % | G16: 0.06 | H16: 0.055 | I16: 0.05 | J16: 0.045 | K16: 0.045
A17: Order Book Execution Rate % (Revenue Recognition) | B17: % | G17: 0.39 | H17: 0.395 | I17: 0.4 | J17: 0.405 | K17: 0.41
A18: D. SEGMENT 3 - ENGINEERING PRODUCTS & SERVICES
A19: Engineering Products Segment Revenue Growth % | B19: % | D19: =Hist_IS!D9/Hist_IS!C9-1 -> 0.12643678 | E19: =Hist_IS!E9/Hist_IS!D9-1 -> -0.032312925 | F19: =Hist_IS!F9/Hist_IS!E9-1 -> 0.052724077 | G19: 0.049 | H19: 0.049 | I19: 0.049 | J19: 0.049 | K19: 0.049
A20: E. MARGIN & COST ASSUMPTIONS (% of Revenue unless noted)
A21: COGS % | B21: % | C21: =(Hist_IS!C14+Hist_IS!C15+Hist_IS!C16)/Hist_IS!C12 -> 0.77671334 | D21: =(Hist_IS!D14+Hist_IS!D15+Hist_IS!D16)/Hist_IS!D12 -> 0.7863152 | E21: =(Hist_IS!E14+Hist_IS!E15+Hist_IS!E16)/Hist_IS!E12 -> 0.77596834 | F21: =(Hist_IS!F14+Hist_IS!F15+Hist_IS!F16)/Hist_IS!F12 -> 0.77704458 | G21: 0.777 | H21: 0.776 | I21: 0.775 | J21: 0.775 | K21: 0.774
A22: Employee Cost % | B22: % | C22: =Hist_IS!C17/Hist_IS!C12 -> 0.070217918 | D22: =Hist_IS!D17/Hist_IS!D12 -> 0.062414871 | E22: =Hist_IS!E17/Hist_IS!E12 -> 0.057743463 | F22: =Hist_IS!F17/Hist_IS!F12 -> 0.065917866 | G22: 0.06 | H22: 0.06 | I22: 0.06 | J22: 0.06 | K22: 0.06
A23: Other Expenses (Selling+Mktg+Admin+Warranty+Other) % | B23: % | C23: =Hist_IS!C19/Hist_IS!C12 -> 0.092746605 | D23: =Hist_IS!D19/Hist_IS!D12 -> 0.1132922 | E23: =Hist_IS!E19/Hist_IS!E12 -> 0.093816908 | F23: =Hist_IS!F19/Hist_IS!F12 -> 0.11154791 | G23: 0.1 | H23: 0.095 | I23: 0.093 | J23: 0.093 | K23: 0.093
A24: Implied EBITDA Margin % (memo, computed on Cost_Schedule) | B24: % | C24: =Cost_Schedule!C19 -> 0.060322139 | D24: =Cost_Schedule!D19 -> 0.037977726 | E24: =Cost_Schedule!E19 -> 0.07247129 | F24: =Cost_Schedule!F19 -> 0.045489645 | G24: =Cost_Schedule!G19 -> 0.063 | H24: =Cost_Schedule!H19 -> 0.069 | I24: =Cost_Schedule!I19 -> 0.072 | J24: =Cost_Schedule!J19 -> 0.072 | K24: =Cost_Schedule!K19 -> 0.073
A25: Effective Tax Rate % | B25: % | G25: 0.3 | H25: 0.3 | I25: 0.3 | J25: 0.3 | K25: 0.3
A26: F. WORKING CAPITAL ASSUMPTIONS (Days)
A27: Receivable Days (DSO, on revenue) | B27: Days | G27: 71 | H27: 77 | I27: 76 | J27: 77 | K27: 76
A28: Inventory Days (DIO, on COGS) | B28: Days | G28: 102 | H28: 97 | I28: 95 | J28: 97 | K28: 94
A29: Payable Days (DPO, on COGS) | B29: Days | G29: 158 | H29: 153 | I29: 153 | J29: 150 | K29: 150
A30: Other Current Assets Days (on revenue) - values USED by WC_Schedule | B30: Days | G30: 67 | H30: 63 | I30: 61 | J30: 61 | K30: 60
A31: Memo: value DISPLAYED on published Assumptions page (not used - see Error_Log E-05) | B31: Days | G31: 25 | H31: 25 | I31: 25 | J31: 25 | K31: 25
A32: Other Current Liabilities Days (on revenue) | B32: Days | G32: 40 | H32: 40 | I32: 40 | J32: 40 | K32: 40
A33: G. DEBT & FINANCING ASSUMPTIONS
A34: LT Debt Repayment % of Opening Balance | B34: % | G34: 0.15 | H34: 0.15 | I34: 0.15 | J34: 0.15 | K34: 0.15
A35: ST Borrowings % (Receivables + Inventory) | B35: % | C35: =Hist_BS!C18/(Hist_BS!C36+Hist_BS!C35) -> 0.15724101 | D35: =Hist_BS!D18/(Hist_BS!D36+Hist_BS!D35) -> 0.10389889 | E35: =Hist_BS!E18/(Hist_BS!E36+Hist_BS!E35) -> 0.092039801 | F35: =Hist_BS!F18/(Hist_BS!F36+Hist_BS!F35) -> 0.091372913 | G35: 0.095 | H35: 0.093 | I35: 0.093 | J35: 0.093 | K35: 0.093
A36: Average Interest Rate LT (NOT USED in model - see Error_Log E-12) | B36: % | G36: 0.07 | H36: 0.072 | I36: 0.069 | J36: 0.067 | K36: 0.067
A37: Average Interest Rate ST (NOT USED in model - see Error_Log E-12) | B37: % | G37: 0.079 | H37: 0.08 | I37: 0.077 | J37: 0.075 | K37: 0.075
A38: Finance Cost % Revenue (inputs set to reproduce published output; page shows 0.6/0.6/0.5/0.5/0.5) | B38: % | C38: =Hist_IS!C26/Hist_IS!C12 -> 0.0031582272 | D38: =Hist_IS!D26/Hist_IS!D12 -> 0.00448682 | E38: =Hist_IS!E26/Hist_IS!E12 -> 0.0040225783 | F38: =Hist_IS!F26/Hist_IS!F12 -> 0.0061074061 | G38: 0.0061 | H38: 0.0055 | I38: 0.005 | J38: 0.005 | K38: 0.005
A39: Other Income % Revenue (inputs set to reproduce published output; page shows 2.0/1.8/2.0/1.9/2.0) | B39: % | C39: =Hist_IS!C27/Hist_IS!C12 -> 0.017686072 | D39: =Hist_IS!D27/Hist_IS!D12 -> 0.020270812 | E39: =Hist_IS!E27/Hist_IS!E12 -> 0.021021216 | F39: =Hist_IS!F27/Hist_IS!F12 -> 0.016707617 | G39: 0.02 | H39: 0.018 | I39: 0.02 | J39: 0.0187 | K39: 0.02
A40: H. DIVIDEND
A41: Dividend per share (Rs) - held flat | B41: Rs | G41: 4 | H41: 4 | I41: 4 | J41: 4 | K41: 4

Sheet Revenue_Build
A1: VOLTAS LIMITED - SEGMENT REVENUE BUILD-UP (Volume x Realization)
A2: INR Crore unless stated
C4: HISTORICAL | G4: FORECAST
A5: Particulars | B5: Unit | C5: Mar-23A | D5: Mar-24A | E5: Mar-25A | F5: Mar-26A | G5: Mar-27E | H5: Mar-28E | I5: Mar-29E | J5: Mar-30E | K5: Mar-31E
A6: SEGMENT 1: UNITARY COOLING PRODUCTS (ROOM AC & COOLERS)
A7: Volume Growth % YoY | G7: =Assumptions!G13 -> 0.16 | H7: =Assumptions!H13 -> 0.1446875 | I7: =Assumptions!I13 -> 0.12 | J7: =Assumptions!J13 -> 0.10297619 | K7: =Assumptions!K13 -> 0.10541176
A8: Realization / ASP Growth % YoY | G8: =Assumptions!G14 -> 0.06 | H8: =Assumptions!H14 -> 0.035 | I8: =Assumptions!I14 -> 0.03 | J8: =Assumptions!J14 -> 0.025 | K8: =Assumptions!K14 -> 0.025
A9: RAC Segment Revenue | C9: =Hist_IS!C7 -> 6475 | D9: =Hist_IS!D7 -> 8160 | E9: =Hist_IS!E7 -> 10614 | F9: =Hist_IS!F7 -> 9501 | G9: =F9*(1+G7)*(1+G8) -> 11682.43 | H9: =G9*(1+H7)*(1+H8) -> 13840.777 | I9: =H9*(1+I7)*(1+I8) -> 15966.72 | J9: =I9*(1+J7)*(1+J8) -> 18051.185 | K9: =J9*(1+K7)*(1+K8) -> 20452.842
A10: SEGMENT 2: ELECTRO-MECHANICAL PROJECTS & SERVICES (EMPS)
A11: Opening Order Book | G11: =F15 -> 6200 | H11: =G15 -> 6497.72 | I11: =H15 -> 6772.7209 | J11: =I15 -> 7022.6543 | K11: =J15 -> 7244.889
A12: New Order Inflow | F12: 4200 | G12: =F12*(1+Assumptions!G16) -> 4452 | H12: =G12*(1+Assumptions!H16) -> 4696.86 | I12: =H12*(1+Assumptions!I16) -> 4931.703 | J12: =I12*(1+Assumptions!J16) -> 5153.6296 | K12: =J12*(1+Assumptions!K16) -> 5385.543
A13: Execution Rate % (of Opening OB + New Orders) | C13: 0.245 | D13: 0.314 | E13: 0.39 | F13: 0.395 | G13: =Assumptions!G17 -> 0.39 | H13: =Assumptions!H17 -> 0.395 | I13: =Assumptions!I17 -> 0.4 | J13: =Assumptions!J17 -> 0.405 | K13: =Assumptions!K17 -> 0.41
A14: EMPS Segment Revenue (Revenue Recognized) | C14: =Hist_IS!C8 -> 2403 | D14: =Hist_IS!D8 -> 3683 | E14: =Hist_IS!E8 -> 4157 | F14: =Hist_IS!F8 -> 4053 | G14: =G13*(G11+G12) -> 4154.28 | H14: =H13*(H11+H12) -> 4421.8591 | I14: =I13*(I11+I12) -> 4681.7696 | J14: =J13*(J11+J12) -> 4931.395 | K14: =K13*(K11+K12) -> 5178.4771
A15: Closing Order Book | C15: 7414 | D15: 8054 | E15: 6500 | F15: 6200 | G15: =G11+G12-G14 -> 6497.72 | H15: =H11+H12-H14 -> 6772.7209 | I15: =I11+I12-I14 -> 7022.6543 | J15: =J11+J12-J14 -> 7244.889 | K15: =K11+K12-K14 -> 7451.9548
A16: Check: FY26 execution rate recomputed = EMPS revenue / (FY25 closing OB + FY26 new orders) | F16: =F14/(E15+F12) -> 0.37878505
A17: Check: FY26 order-book roll-forward = Opening OB + New orders - Revenue - Closing OB (should be 0) | F17: =E15+F12-F14-F15 -> 447
A18: SEGMENT 3: ENGINEERING PRODUCTS & SERVICES
A19: Segment Revenue Growth % YoY | D19: =D20/C20-1 -> 0.12643678 | E19: =E20/D20-1 -> -0.032312925 | F19: =F20/E20-1 -> 0.052724077 | G19: =Assumptions!G19 -> 0.049 | H19: =Assumptions!H19 -> 0.049 | I19: =Assumptions!I19 -> 0.049 | J19: =Assumptions!J19 -> 0.049 | K19: =Assumptions!K19 -> 0.049
A20: Engineering Products & Services Revenue | C20: =Hist_IS!C9 -> 522 | D20: =Hist_IS!D9 -> 588 | E20: =Hist_IS!E9 -> 569 | F20: =Hist_IS!F9 -> 599 | G20: =F20*(1+G19) -> 628.351 | H20: =G20*(1+H19) -> 659.1402 | I20: =H20*(1+I19) -> 691.43807 | J20: =I20*(1+J19) -> 725.31853 | K20: =J20*(1+K19) -> 760.85914
A22: Others / Unallocated Revenue | C22: =Hist_IS!C11 -> 99 | D22: =Hist_IS!D11 -> 50 | E22: =Hist_IS!E11 -> 73 | F22: =Hist_IS!F11 -> 92 | G22: =F22 -> 92 | H22: =G22 -> 92 | I22: =H22 -> 92 | J22: =I22 -> 92 | K22: =J22 -> 92
A24: TOTAL REVENUE FROM OPERATIONS | C24: =C9+C14+C20+C22 -> 9499 | D24: =D9+D14+D20+D22 -> 12481 | E24: =E9+E14+E20+E22 -> 15413 | F24: =F9+F14+F20+F22 -> 14245 | G24: =G9+G14+G20+G22 -> 16557.061 | H24: =H9+H14+H20+H22 -> 19013.776 | I24: =I9+I14+I20+I22 -> 21431.928 | J24: =J9+J14+J20+J22 -> 23799.898 | K24: =K9+K14+K20+K22 -> 26484.178

Sheet Cost_Schedule
A1: VOLTAS LIMITED - OPERATING COST DRIVER SCHEDULE
A2: INR Crore unless stated
C4: HISTORICAL | G4: FORECAST
A5: Particulars | B5: Unit | C5: Mar-23A | D5: Mar-24A | E5: Mar-25A | F5: Mar-26A | G5: Mar-27E | H5: Mar-28E | I5: Mar-29E | J5: Mar-30E | K5: Mar-31E
A6: Total Revenue (link) | C6: =Revenue_Build!C24 -> 9499 | D6: =Revenue_Build!D24 -> 12481 | E6: =Revenue_Build!E24 -> 15413 | F6: =Revenue_Build!F24 -> 14245 | G6: =Revenue_Build!G24 -> 16557.061 | H6: =Revenue_Build!H24 -> 19013.776 | I6: =Revenue_Build!I24 -> 21431.928 | J6: =Revenue_Build!J24 -> 23799.898 | K6: =Revenue_Build!K24 -> 26484.178
A8: Cost of Goods Sold - % of Revenue | C8: =Assumptions!C21 -> 0.77671334 | D8: =Assumptions!D21 -> 0.7863152 | E8: =Assumptions!E21 -> 0.77596834 | F8: =Assumptions!F21 -> 0.77704458 | G8: =Assumptions!G21 -> 0.777 | H8: =Assumptions!H21 -> 0.776 | I8: =Assumptions!I21 -> 0.775 | J8: =Assumptions!J21 -> 0.775 | K8: =Assumptions!K21 -> 0.774
A9: Cost of Goods Sold | C9: =Hist_IS!C14+Hist_IS!C15+Hist_IS!C16 -> 7378 | D9: =Hist_IS!D14+Hist_IS!D15+Hist_IS!D16 -> 9814 | E9: =Hist_IS!E14+Hist_IS!E15+Hist_IS!E16 -> 11960 | F9: =Hist_IS!F14+Hist_IS!F15+Hist_IS!F16 -> 11069 | G9: =G6*G8 -> 12864.836 | H9: =H6*H8 -> 14754.69 | I9: =I6*I8 -> 16609.744 | J9: =J6*J8 -> 18444.921 | K9: =K6*K8 -> 20498.754
A11: Employee Benefit Expense - % of Revenue | C11: =Assumptions!C22 -> 0.070217918 | D11: =Assumptions!D22 -> 0.062414871 | E11: =Assumptions!E22 -> 0.057743463 | F11: =Assumptions!F22 -> 0.065917866 | G11: =Assumptions!G22 -> 0.06 | H11: =Assumptions!H22 -> 0.06 | I11: =Assumptions!I22 -> 0.06 | J11: =Assumptions!J22 -> 0.06 | K11: =Assumptions!K22 -> 0.06
A12: Employee Benefit Expense | C12: =Hist_IS!C17 -> 667 | D12: =Hist_IS!D17 -> 779 | E12: =Hist_IS!E17 -> 890 | F12: =Hist_IS!F17 -> 939 | G12: =G6*G11 -> 993.42364 | H12: =H6*H11 -> 1140.8266 | I12: =I6*I11 -> 1285.9157 | J12: =J6*J11 -> 1427.9939 | K12: =K6*K11 -> 1589.0507
A14: Other Expenses (Selling+Mktg+Admin+Other) - % of Revenue | C14: =Assumptions!C23 -> 0.092746605 | D14: =Assumptions!D23 -> 0.1132922 | E14: =Assumptions!E23 -> 0.093816908 | F14: =Assumptions!F23 -> 0.11154791 | G14: =Assumptions!G23 -> 0.1 | H14: =Assumptions!H23 -> 0.095 | I14: =Assumptions!I23 -> 0.093 | J14: =Assumptions!J23 -> 0.093 | K14: =Assumptions!K23 -> 0.093
A15: Other Expenses (published label: "Sub-Contracting / Erection Charges (EMPS)" - mislabelled, see E-11) | C15: =Hist_IS!C19 -> 881 | D15: =Hist_IS!D19 -> 1414 | E15: =Hist_IS!E19 -> 1446 | F15: =Hist_IS!F19 -> 1589 | G15: =G6*G14 -> 1655.7061 | H15: =H6*H14 -> 1806.3087 | I15: =I6*I14 -> 1993.1693 | J15: =J6*J14 -> 2213.3905 | K15: =K6*K14 -> 2463.0286
A17: Total Operating Expenses | C17: =C9+C12+C15 -> 8926 | D17: =D9+D12+D15 -> 12007 | E17: =E9+E12+E15 -> 14296 | F17: =F9+F12+F15 -> 13597 | G17: =G9+G12+G15 -> 15513.966 | H17: =H9+H12+H15 -> 17701.825 | I17: =I9+I12+I15 -> 19888.829 | J17: =J9+J12+J15 -> 22086.306 | K17: =K9+K12+K15 -> 24550.833
A18: EBITDA (Revenue - Total Operating Expenses) | C18: =C6-C17 -> 573 | D18: =D6-D17 -> 474 | E18: =E6-E17 -> 1117 | F18: =F6-F17 -> 648 | G18: =G6-G17 -> 1043.0948 | H18: =H6-H17 -> 1311.9505 | I18: =I6-I17 -> 1543.0988 | J18: =J6-J17 -> 1713.5927 | K18: =K6-K17 -> 1933.345
A19: EBITDA Margin % | C19: =C18/C6 -> 0.060322139 | D19: =D18/D6 -> 0.037977726 | E19: =E18/E6 -> 0.07247129 | F19: =F18/F6 -> 0.045489645 | G19: =G18/G6 -> 0.063 | H19: =H18/H6 -> 0.069 | I19: =I18/I6 -> 0.072 | J19: =J18/J6 -> 0.072 | K19: =K18/K6 -> 0.073

Sheet WC_Schedule
A1: VOLTAS LIMITED - WORKING CAPITAL SCHEDULE
A2: INR Crore unless stated
C4: HISTORICAL | G4: FORECAST
A5: Particulars | B5: Unit | C5: Mar-23A | D5: Mar-24A | E5: Mar-25A | F5: Mar-26A | G5: Mar-27E | H5: Mar-28E | I5: Mar-29E | J5: Mar-30E | K5: Mar-31E
A6: Total Revenue (link) | C6: =Cost_Schedule!C6 -> 9499 | D6: =Cost_Schedule!D6 -> 12481 | E6: =Cost_Schedule!E6 -> 15413 | F6: =Cost_Schedule!F6 -> 14245 | G6: =Cost_Schedule!G6 -> 16557.061 | H6: =Cost_Schedule!H6 -> 19013.776 | I6: =Cost_Schedule!I6 -> 21431.928 | J6: =Cost_Schedule!J6 -> 23799.898 | K6: =Cost_Schedule!K6 -> 26484.178
A7: Cost of Goods Sold | C7: =Cost_Schedule!C9 -> 7378 | D7: =Cost_Schedule!D9 -> 9814 | E7: =Cost_Schedule!E9 -> 11960 | F7: =Cost_Schedule!F9 -> 11069 | G7: =Cost_Schedule!G9 -> 12864.836 | H7: =Cost_Schedule!H9 -> 14754.69 | I7: =Cost_Schedule!I9 -> 16609.744 | J7: =Cost_Schedule!J9 -> 18444.921 | K7: =Cost_Schedule!K9 -> 20498.754
A8: DAYS OUTSTANDING (Historical = computed | Forecast = Assumptions link)
A9: Trade Receivable Days (on Revenue) | C9: =Hist_BS!C36/C6*365 -> 84.227813 | D9: =Hist_BS!D36/D6*365 -> 74.076196 | E9: =Hist_BS!E36/E6*365 -> 59.463764 | F9: =Hist_BS!F36/F6*365 -> 77.765883 | G9: =Assumptions!G27 -> 71 | H9: =Assumptions!H27 -> 77 | I9: =Assumptions!I27 -> 76 | J9: =Assumptions!J27 -> 77 | K9: =Assumptions!K27 -> 76
A10: Inventory Days (on COGS) | C10: =Hist_BS!C35/C7*365 -> 78.758471 | D10: =Hist_BS!D35/D7*365 -> 79.404422 | E10: =Hist_BS!E35/E7*365 -> 82.857441 | F10: =Hist_BS!F35/F7*365 -> 113.20309 | G10: =Assumptions!G28 -> 102 | H10: =Assumptions!H28 -> 97 | I10: =Assumptions!I28 -> 95 | J10: =Assumptions!J28 -> 97 | K10: =Assumptions!K28 -> 94
A11: Trade Payable Days (on COGS) | C11: =Hist_BS!C20/C7*365 -> 149.05733 | D11: =Hist_BS!D20/D7*365 -> 143.41145 | E11: =Hist_BS!E20/E7*365 -> 118.80811 | F11: =Hist_BS!F20/F7*365 -> 172.39317 | G11: =Assumptions!G29 -> 158 | H11: =Assumptions!H29 -> 153 | I11: =Assumptions!I29 -> 153 | J11: =Assumptions!J29 -> 150 | K11: =Assumptions!K29 -> 150
A12: Other Current Assets Days (on Revenue) | C12: =(Hist_BS!C39+Hist_BS!C40)/C6*365 -> 63.286135 | D12: =(Hist_BS!D39+Hist_BS!D40)/D6*365 -> 49.803301 | E12: =(Hist_BS!E39+Hist_BS!E40)/E6*365 -> 60.979368 | F12: =(Hist_BS!F39+Hist_BS!F40)/F6*365 -> 71.821341 | G12: =Assumptions!G30 -> 67 | H12: =Assumptions!H30 -> 63 | I12: =Assumptions!I30 -> 61 | J12: =Assumptions!J30 -> 61 | K12: =Assumptions!K30 -> 60
A13: Other Current Liabilities Days (on Revenue) | C13: =Hist_BS!C21/C6*365 -> 38.540373 | D13: =Hist_BS!D21/D6*365 -> 41.117699 | E13: =Hist_BS!E21/E6*365 -> 38.3874 | F13: =Hist_BS!F21/F6*365 -> 44.174096 | G13: =Assumptions!G32 -> 40 | H13: =Assumptions!H32 -> 40 | I13: =Assumptions!I32 -> 40 | J13: =Assumptions!J32 -> 40 | K13: =Assumptions!K32 -> 40
A14: WORKING CAPITAL BALANCES (Rs Cr)
A15: Trade Receivables | C15: =Hist_BS!C36 -> 2192 | D15: =Hist_BS!D36 -> 2533 | E15: =Hist_BS!E36 -> 2511 | F15: =Hist_BS!F36 -> 3035 | G15: =G6*G9/365 -> 3220.6885 | H15: =H6*H9/365 -> 4011.1254 | I15: =I6*I9/365 -> 4462.5384 | J15: =J6*J9/365 -> 5020.8005 | K15: =K6*K9/365 -> 5514.5138
A16: Inventories | C16: =Hist_BS!C35 -> 1592 | D16: =Hist_BS!D35 -> 2135 | E16: =Hist_BS!E35 -> 2715 | F16: =Hist_BS!F35 -> 3433 | G16: =G7*G10/365 -> 3595.1049 | H16: =H7*H10/365 -> 3921.1094 | I16: =I7*I10/365 -> 4323.084 | J16: =J7*J10/365 -> 4901.801 | K16: =K7*K10/365 -> 5279.1311
A17: Other Current Assets (incl. contract assets) | C17: =Hist_BS!C39+Hist_BS!C40 -> 1647 | D17: =Hist_BS!D39+Hist_BS!D40 -> 1703 | E17: =Hist_BS!E39+Hist_BS!E40 -> 2575 | F17: =Hist_BS!F39+Hist_BS!F40 -> 2803 | G17: =G6*G12/365 -> 3039.2413 | H17: =H6*H12/365 -> 3281.8298 | I17: =I6*I12/365 -> 3581.7742 | J17: =J6*J12/365 -> 3977.5173 | K17: =K6*K12/365 -> 4353.5635
A18: Trade Payables | C18: =Hist_BS!C20 -> 3013 | D18: =Hist_BS!D20 -> 3856 | E18: =Hist_BS!E20 -> 3893 | F18: =Hist_BS!F20 -> 5228 | G18: =G7*G11/365 -> 5568.8879 | H18: =H7*H11/365 -> 6184.8427 | I18: =I7*I11/365 -> 6962.4406 | J18: =J7*J11/365 -> 7580.1046 | K18: =K7*K11/365 -> 8424.1454
A19: Other Current Liabilities | C19: =Hist_BS!C21 -> 1003 | D19: =Hist_BS!D21 -> 1406 | E19: =Hist_BS!E21 -> 1621 | F19: =Hist_BS!F21 -> 1724 | G19: =G6*G13/365 -> 1814.4724 | H19: =H6*H13/365 -> 2083.7015 | I19: =I6*I13/365 -> 2348.7044 | J19: =J6*J13/365 -> 2608.208 | K19: =K6*K13/365 -> 2902.3757
A21: Net Working Capital (AR+Inv+OCA-AP-OCL) | C21: =C15+C16+C17-C18-C19 -> 1415 | D21: =D15+D16+D17-D18-D19 -> 1109 | E21: =E15+E16+E17-E18-E19 -> 2287 | F21: =F15+F16+F17-F18-F19 -> 2319 | G21: =G15+G16+G17-G18-G19 -> 2471.6743 | H21: =H15+H16+H17-H18-H19 -> 2945.5204 | I21: =I15+I16+I17-I18-I19 -> 3056.2516 | J21: =J15+J16+J17-J18-J19 -> 3711.8061 | K21: =K15+K16+K17-K18-K19 -> 3820.6874
A22: (Increase) / Decrease in NWC [Cash Flow Impact] | G22: =F21-G21 -> -152.6743 | H22: =G21-H21 -> -473.84612 | I22: =H21-I21 -> -110.73119 | J22: =I21-J21 -> -655.55447 | K22: =J21-K21 -> -108.88128

Sheet Capex_Dep
A1: VOLTAS LIMITED - CAPEX & DEPRECIATION SCHEDULE
A2: INR Crore unless stated
C4: HISTORICAL | G4: FORECAST
A5: Particulars | B5: Unit | C5: Mar-23A | D5: Mar-24A | E5: Mar-25A | F5: Mar-26A | G5: Mar-27E | H5: Mar-28E | I5: Mar-29E | J5: Mar-30E | K5: Mar-31E
A6: Total Revenue | C6: =Revenue_Build!C24 -> 9499 | D6: =Revenue_Build!D24 -> 12481 | E6: =Revenue_Build!E24 -> 15413 | F6: =Revenue_Build!F24 -> 14245 | G6: =Revenue_Build!G24 -> 16557.061 | H6: =Revenue_Build!H24 -> 19013.776 | I6: =Revenue_Build!I24 -> 21431.928 | J6: =Revenue_Build!J24 -> 23799.898 | K6: =Revenue_Build!K24 -> 26484.178
A7: GROSS BLOCK ROLL-FORWARD - PPE (Rs Cr)
A8: Opening Gross Block | C8: 488 | D8: =C12 -> 638 | E8: =D12 -> 687 | F8: =E12 -> 1161 | G8: =F12 -> 1338 | H8: =G12 -> 1553.2418 | I8: =H12 -> 1800.4209 | J8: =I12 -> 2143.3317 | K8: =J12 -> 2452.7304
A9: Add: Capex | C9: 159 | D9: 63 | E9: 483 | F9: 183 | G9: =G6*G23 -> 215.24179 | H9: =H6*H23 -> 247.17909 | I9: =I6*I23 -> 342.91084 | J9: =J6*J23 -> 309.39868 | K9: =K6*K23 -> 344.29432
A10: Less: Disposal | C10: 13 | D10: 14 | E10: 11 | F10: 17
A11: Add: Other adjustments / transfers (shown in PDF as a 2nd "Less: Disposal" row - see E-08) | C11: 4 | D11: 1 | E11: 1 | F11: 11
A12: Closing Gross Block | C12: 638 | D12: 687 | E12: 1161 | F12: 1338 | G12: =G8+G9-N(G10)+N(G11) -> 1553.2418 | H12: =H8+H9-N(H10)+N(H11) -> 1800.4209 | I12: =I8+I9-N(I10)+N(I11) -> 2143.3317 | J12: =J8+J9-N(J10)+N(J11) -> 2452.7304 | K12: =K8+K9-N(K10)+N(K11) -> 2797.0247
A13: Check: roll-forward difference (rounding in source data) | C13: =C8+C9-C10+C11-C12 -> 0 | D13: =D8+D9-D10+D11-D12 -> 1 | E13: =E8+E9-E10+E11-E12 -> -1 | F13: =F8+F9-F10+F11-F12 -> 0
A14: DEPRECIATION & ACCUMULATED DEPRECIATION - PPE (Rs Cr)
A15: Opening Accumulated Depreciation | C15: 258 | D15: =C19 -> 277 | E15: =D19 -> 297 | F15: =E19 -> 341 | G15: =F19 -> 403 | H15: =G19 -> 482.78372 | I15: =H19 -> 573.80285 | J15: =I19 -> 680.40884 | K15: =J19 -> 801.0784
A16: Add: Dep exp | C16: 27 | D16: 32 | E16: 52 | F16: 70 | G16: =G33 -> 79.783718 | H16: =H33 -> 91.019131 | I16: =I33 -> 106.60599 | J16: =J33 -> 120.66956 | K16: =K33 -> 136.31931
A17: Less: Disposal | C17: 11 | D17: 13 | E17: 9 | F17: 15
A18: Add: Other adjustments (shown in PDF as a 2nd "Less: Disposal" row) | C18: 4 | D18: 1 | E18: 1 | F18: 7
A19: Closing Accumulated Depreciation | C19: 277 | D19: 297 | E19: 341 | F19: 403 | G19: =G15+G16-N(G17)+N(G18) -> 482.78372 | H19: =H15+H16-N(H17)+N(H18) -> 573.80285 | I19: =I15+I16-N(I17)+N(I18) -> 680.40884 | J19: =J15+J16-N(J17)+N(J18) -> 801.0784 | K19: =K15+K16-N(K17)+N(K18) -> 937.3977
A20: Check: roll-forward difference (rounding in source data) | C20: =C15+C16-C17+C18-C19 -> 1 | D20: =D15+D16-D17+D18-D19 -> 0 | E20: =E15+E16-E17+E18-E19 -> 0 | F20: =F15+F16-F17+F18-F19 -> 0
A21: Closing Net Block (Gross Block - Acc. Depreciation) | C21: =C12-C19 -> 361 | D21: =D12-D19 -> 390 | E21: =E12-E19 -> 820 | F21: =F12-F19 -> 935 | G21: =G12-G19 -> 1070.4581 | H21: =H12-H19 -> 1226.618 | I21: =I12-I19 -> 1462.9229 | J21: =J12-J19 -> 1651.652 | K21: =K12-K19 -> 1859.627
A23: CAPEX % Sales | C23: =C9/C6 -> 0.016738604 | D23: =D9/D6 -> 0.0050476725 | E23: =E9/E6 -> 0.031337183 | F23: =F9/F6 -> 0.012846613 | G23: 0.013 | H23: 0.013 | I23: 0.016 | J23: 0.013 | K23: 0.013
A24: Depreciation % Gross Block | C24: =C16/C12 -> 0.042319749 | D24: =D16/D12 -> 0.04657933 | E24: =E16/E12 -> 0.044788975 | F24: =F16/F12 -> 0.052316891 | G24: =1/G25 -> 0.045454545 | H24: =1/H25 -> 0.045454545 | I24: =1/I25 -> 0.045454545 | J24: =1/J25 -> 0.045454545 | K24: =1/K25 -> 0.045454545
A25: Avg Life (years) | C25: =1/C24 -> 23.62963 | D25: =1/D24 -> 21.46875 | E25: =1/E24 -> 22.326923 | F25: =1/F24 -> 19.114286 | G25: 22 | H25: 22 | I25: 22 | J25: 22 | K25: 22
A26: DEPRECIATION WATERFALL - PPE (depreciation on each year's capex over average life)
A27: Depreciation on existing block (held at FY26 level) | G27: =$F$16 -> 70 | H27: =$F$16 -> 70 | I27: =$F$16 -> 70 | J27: =$F$16 -> 70 | K27: =$F$16 -> 70
A28: Year 1 capex (Mar-27E) | G28: =$G$9/G$25 -> 9.7837176 | H28: =$G$9/H$25 -> 9.7837176 | I28: =$G$9/I$25 -> 9.7837176 | J28: =$G$9/J$25 -> 9.7837176 | K28: =$G$9/K$25 -> 9.7837176
